Sat Jul 12 17:28:27 2025 - Erreur : Traceback (most recent call last):
  File "D:\admin\MES PROJETS\Bot de trading\core\trade_executor.py", line 146, in open_trade
    order = retry_order_creation(lambda: client.futures_create_order(
  File "D:\admin\MES PROJETS\Bot de trading\core\trade_executor.py", line 66, in retry_order_creation
    raise last_exception
  File "D:\admin\MES PROJETS\Bot de trading\core\trade_executor.py", line 61, in retry_order_creation
    return order_fn()
  File "D:\admin\MES PROJETS\Bot de trading\core\trade_executor.py", line 146, in <lambda>
    order = retry_order_creation(lambda: client.futures_create_order(
  File "C:\Users\user\AppData\Local\Programs\Python\Python310\lib\site-packages\binance\client.py", line 7659, in futures_create_order
    return self._request_futures_api("post", "order", True, data=params)
  File "C:\Users\user\AppData\Local\Programs\Python\Python310\lib\site-packages\binance\client.py", line 126, in _request_futures_api
    return self._request(method, uri, signed, force_params, **kwargs)
  File "C:\Users\user\AppData\Local\Programs\Python\Python310\lib\site-packages\binance\client.py", line 89, in _request
    return self._handle_response(self.response)
  File "C:\Users\user\AppData\Local\Programs\Python\Python310\lib\site-packages\binance\client.py", line 98, in _handle_response
    raise BinanceAPIException(response, response.status_code, response.text)
binance.exceptions.BinanceAPIException: APIError(code=-2019): Margin is insufficient.

Sat Jul 12 17:33:31 2025 - Erreur : Traceback (most recent call last):
  File "D:\admin\MES PROJETS\Bot de trading\core\trade_executor.py", line 140, in open_trade
    order = retry_order_creation(lambda: client.futures_create_order(
  File "D:\admin\MES PROJETS\Bot de trading\core\trade_executor.py", line 66, in retry_order_creation
    raise last_exception
  File "D:\admin\MES PROJETS\Bot de trading\core\trade_executor.py", line 61, in retry_order_creation
    return order_fn()
  File "D:\admin\MES PROJETS\Bot de trading\core\trade_executor.py", line 140, in <lambda>
    order = retry_order_creation(lambda: client.futures_create_order(
  File "C:\Users\user\AppData\Local\Programs\Python\Python310\lib\site-packages\binance\client.py", line 7659, in futures_create_order
    return self._request_futures_api("post", "order", True, data=params)
  File "C:\Users\user\AppData\Local\Programs\Python\Python310\lib\site-packages\binance\client.py", line 126, in _request_futures_api
    return self._request(method, uri, signed, force_params, **kwargs)
  File "C:\Users\user\AppData\Local\Programs\Python\Python310\lib\site-packages\binance\client.py", line 89, in _request
    return self._handle_response(self.response)
  File "C:\Users\user\AppData\Local\Programs\Python\Python310\lib\site-packages\binance\client.py", line 98, in _handle_response
    raise BinanceAPIException(response, response.status_code, response.text)
binance.exceptions.BinanceAPIException: APIError(code=-2019): Margin is insufficient.

Sat Jul 12 22:21:12 2025 - Erreur : Traceback (most recent call last):
  File "D:\admin\MES PROJETS\Bot de trading\core\trade_executor.py", line 162, in open_trade
    order = retry_order_creation(lambda: client.futures_create_order(
  File "D:\admin\MES PROJETS\Bot de trading\core\trade_executor.py", line 79, in retry_order_creation
    raise last_exception
  File "D:\admin\MES PROJETS\Bot de trading\core\trade_executor.py", line 74, in retry_order_creation
    return order_fn()
  File "D:\admin\MES PROJETS\Bot de trading\core\trade_executor.py", line 162, in <lambda>
    order = retry_order_creation(lambda: client.futures_create_order(
  File "C:\Users\user\AppData\Local\Programs\Python\Python310\lib\site-packages\binance\client.py", line 7659, in futures_create_order
    return self._request_futures_api("post", "order", True, data=params)
  File "C:\Users\user\AppData\Local\Programs\Python\Python310\lib\site-packages\binance\client.py", line 126, in _request_futures_api
    return self._request(method, uri, signed, force_params, **kwargs)
  File "C:\Users\user\AppData\Local\Programs\Python\Python310\lib\site-packages\binance\client.py", line 89, in _request
    return self._handle_response(self.response)
  File "C:\Users\user\AppData\Local\Programs\Python\Python310\lib\site-packages\binance\client.py", line 98, in _handle_response
    raise BinanceAPIException(response, response.status_code, response.text)
binance.exceptions.BinanceAPIException: APIError(code=-2019): Margin is insufficient.

Sat Jul 12 22:25:56 2025 - Erreur : Traceback (most recent call last):
  File "D:\admin\MES PROJETS\Bot de trading\core\trade_executor.py", line 156, in open_trade
    order = retry_order_creation(lambda: client.futures_create_order(
  File "D:\admin\MES PROJETS\Bot de trading\core\trade_executor.py", line 79, in retry_order_creation
    raise last_exception
  File "D:\admin\MES PROJETS\Bot de trading\core\trade_executor.py", line 74, in retry_order_creation
    return order_fn()
  File "D:\admin\MES PROJETS\Bot de trading\core\trade_executor.py", line 156, in <lambda>
    order = retry_order_creation(lambda: client.futures_create_order(
  File "C:\Users\user\AppData\Local\Programs\Python\Python310\lib\site-packages\binance\client.py", line 7659, in futures_create_order
    return self._request_futures_api("post", "order", True, data=params)
  File "C:\Users\user\AppData\Local\Programs\Python\Python310\lib\site-packages\binance\client.py", line 126, in _request_futures_api
    return self._request(method, uri, signed, force_params, **kwargs)
  File "C:\Users\user\AppData\Local\Programs\Python\Python310\lib\site-packages\binance\client.py", line 89, in _request
    return self._handle_response(self.response)
  File "C:\Users\user\AppData\Local\Programs\Python\Python310\lib\site-packages\binance\client.py", line 98, in _handle_response
    raise BinanceAPIException(response, response.status_code, response.text)
binance.exceptions.BinanceAPIException: APIError(code=-2019): Margin is insufficient.

Sat Jul 12 22:35:03 2025 - Erreur : Traceback (most recent call last):
  File "D:\admin\MES PROJETS\Bot de trading\core\trade_executor.py", line 155, in open_trade
    order = retry_order_creation(lambda: client.futures_create_order(
  File "D:\admin\MES PROJETS\Bot de trading\core\trade_executor.py", line 79, in retry_order_creation
    raise last_exception
  File "D:\admin\MES PROJETS\Bot de trading\core\trade_executor.py", line 74, in retry_order_creation
    return order_fn()
  File "D:\admin\MES PROJETS\Bot de trading\core\trade_executor.py", line 155, in <lambda>
    order = retry_order_creation(lambda: client.futures_create_order(
  File "C:\Users\user\AppData\Local\Programs\Python\Python310\lib\site-packages\binance\client.py", line 7659, in futures_create_order
    return self._request_futures_api("post", "order", True, data=params)
  File "C:\Users\user\AppData\Local\Programs\Python\Python310\lib\site-packages\binance\client.py", line 126, in _request_futures_api
    return self._request(method, uri, signed, force_params, **kwargs)
  File "C:\Users\user\AppData\Local\Programs\Python\Python310\lib\site-packages\binance\client.py", line 89, in _request
    return self._handle_response(self.response)
  File "C:\Users\user\AppData\Local\Programs\Python\Python310\lib\site-packages\binance\client.py", line 98, in _handle_response
    raise BinanceAPIException(response, response.status_code, response.text)
binance.exceptions.BinanceAPIException: APIError(code=-2019): Margin is insufficient.

Sat Jul 12 22:46:12 2025 - Erreur : Traceback (most recent call last):
  File "D:\admin\MES PROJETS\Bot de trading\core\trade_executor.py", line 154, in open_trade
    order = retry_order_creation(lambda: client.futures_create_order(
  File "D:\admin\MES PROJETS\Bot de trading\core\trade_executor.py", line 79, in retry_order_creation
    raise last_exception
  File "D:\admin\MES PROJETS\Bot de trading\core\trade_executor.py", line 74, in retry_order_creation
    return order_fn()
  File "D:\admin\MES PROJETS\Bot de trading\core\trade_executor.py", line 154, in <lambda>
    order = retry_order_creation(lambda: client.futures_create_order(
  File "C:\Users\user\AppData\Local\Programs\Python\Python310\lib\site-packages\binance\client.py", line 7659, in futures_create_order
    return self._request_futures_api("post", "order", True, data=params)
  File "C:\Users\user\AppData\Local\Programs\Python\Python310\lib\site-packages\binance\client.py", line 126, in _request_futures_api
    return self._request(method, uri, signed, force_params, **kwargs)
  File "C:\Users\user\AppData\Local\Programs\Python\Python310\lib\site-packages\binance\client.py", line 89, in _request
    return self._handle_response(self.response)
  File "C:\Users\user\AppData\Local\Programs\Python\Python310\lib\site-packages\binance\client.py", line 98, in _handle_response
    raise BinanceAPIException(response, response.status_code, response.text)
binance.exceptions.BinanceAPIException: APIError(code=-2019): Margin is insufficient.

Sat Jul 12 22:57:21 2025 - Erreur : Traceback (most recent call last):
  File "D:\admin\MES PROJETS\Bot de trading\core\trade_executor.py", line 154, in open_trade
    order = retry_order_creation(lambda: client.futures_create_order(
  File "D:\admin\MES PROJETS\Bot de trading\core\trade_executor.py", line 79, in retry_order_creation
    raise last_exception
  File "D:\admin\MES PROJETS\Bot de trading\core\trade_executor.py", line 74, in retry_order_creation
    return order_fn()
  File "D:\admin\MES PROJETS\Bot de trading\core\trade_executor.py", line 154, in <lambda>
    order = retry_order_creation(lambda: client.futures_create_order(
  File "C:\Users\user\AppData\Local\Programs\Python\Python310\lib\site-packages\binance\client.py", line 7659, in futures_create_order
    return self._request_futures_api("post", "order", True, data=params)
  File "C:\Users\user\AppData\Local\Programs\Python\Python310\lib\site-packages\binance\client.py", line 126, in _request_futures_api
    return self._request(method, uri, signed, force_params, **kwargs)
  File "C:\Users\user\AppData\Local\Programs\Python\Python310\lib\site-packages\binance\client.py", line 89, in _request
    return self._handle_response(self.response)
  File "C:\Users\user\AppData\Local\Programs\Python\Python310\lib\site-packages\binance\client.py", line 98, in _handle_response
    raise BinanceAPIException(response, response.status_code, response.text)
binance.exceptions.BinanceAPIException: APIError(code=-2019): Margin is insufficient.

Sat Jul 12 22:59:34 2025 - Erreur : Traceback (most recent call last):
  File "C:\Users\user\AppData\Local\Programs\Python\Python310\lib\site-packages\urllib3\connection.py", line 198, in _new_conn
    sock = connection.create_connection(
  File "C:\Users\user\AppData\Local\Programs\Python\Python310\lib\site-packages\urllib3\util\connection.py", line 60, in create_connection
    for res in socket.getaddrinfo(host, port, family, socket.SOCK_STREAM):
  File "C:\Users\user\AppData\Local\Programs\Python\Python310\lib\socket.py", line 955, in getaddrinfo
    for res in _socket.getaddrinfo(host, port, family, type, proto, flags):
socket.gaierror: [Errno 11001] getaddrinfo failed

The above exception was the direct cause of the following exception:

Traceback (most recent call last):
  File "C:\Users\user\AppData\Local\Programs\Python\Python310\lib\site-packages\urllib3\connectionpool.py", line 787, in urlopen
    response = self._make_request(
  File "C:\Users\user\AppData\Local\Programs\Python\Python310\lib\site-packages\urllib3\connectionpool.py", line 488, in _make_request
    raise new_e
  File "C:\Users\user\AppData\Local\Programs\Python\Python310\lib\site-packages\urllib3\connectionpool.py", line 464, in _make_request
    self._validate_conn(conn)
  File "C:\Users\user\AppData\Local\Programs\Python\Python310\lib\site-packages\urllib3\connectionpool.py", line 1093, in _validate_conn
    conn.connect()
  File "C:\Users\user\AppData\Local\Programs\Python\Python310\lib\site-packages\urllib3\connection.py", line 704, in connect
    self.sock = sock = self._new_conn()
  File "C:\Users\user\AppData\Local\Programs\Python\Python310\lib\site-packages\urllib3\connection.py", line 205, in _new_conn
    raise NameResolutionError(self.host, self, e) from e
urllib3.exceptions.NameResolutionError: <urllib3.connection.HTTPSConnection object at 0x000001C43077C370>: Failed to resolve 'fapi.binance.com' ([Errno 11001] getaddrinfo failed)

The above exception was the direct cause of the following exception:

Traceback (most recent call last):
  File "C:\Users\user\AppData\Local\Programs\Python\Python310\lib\site-packages\requests\adapters.py", line 667, in send
    resp = conn.urlopen(
  File "C:\Users\user\AppData\Local\Programs\Python\Python310\lib\site-packages\urllib3\connectionpool.py", line 841, in urlopen
    retries = retries.increment(
  File "C:\Users\user\AppData\Local\Programs\Python\Python310\lib\site-packages\urllib3\util\retry.py", line 519, in increment
    raise MaxRetryError(_pool, url, reason) from reason  # type: ignore[arg-type]
urllib3.exceptions.MaxRetryError: HTTPSConnectionPool(host='fapi.binance.com', port=443): Max retries exceeded with url: /fapi/v3/positionRisk?recvWindow=10000&symbol=ALGOUSDT&timestamp=1752353963761&signature=11a6e8d9d23f74e1e14e63989a156fae29f309db60731c994c633759bf4af6d3 (Caused by NameResolutionError("<urllib3.connection.HTTPSConnection object at 0x000001C43077C370>: Failed to resolve 'fapi.binance.com' ([Errno 11001] getaddrinfo failed)"))

During handling of the above exception, another exception occurred:

Traceback (most recent call last):
  File "D:\admin\MES PROJETS\Bot de trading\core\trade_executor.py", line 334, in cancel_all_open_orders_if_no_position
    positions = client.futures_position_information(symbol=symbol)
  File "C:\Users\user\AppData\Local\Programs\Python\Python310\lib\site-packages\binance\client.py", line 7835, in futures_position_information
    return self._request_futures_api("get", "positionRisk", True, 3, data=params)
  File "C:\Users\user\AppData\Local\Programs\Python\Python310\lib\site-packages\binance\client.py", line 126, in _request_futures_api
    return self._request(method, uri, signed, force_params, **kwargs)
  File "C:\Users\user\AppData\Local\Programs\Python\Python310\lib\site-packages\binance\client.py", line 88, in _request
    self.response = getattr(self.session, method)(uri, headers=headers, data=data, **kwargs)
  File "C:\Users\user\AppData\Local\Programs\Python\Python310\lib\site-packages\requests\sessions.py", line 602, in get
    return self.request("GET", url, **kwargs)
  File "C:\Users\user\AppData\Local\Programs\Python\Python310\lib\site-packages\requests\sessions.py", line 589, in request
    resp = self.send(prep, **send_kwargs)
  File "C:\Users\user\AppData\Local\Programs\Python\Python310\lib\site-packages\requests\sessions.py", line 703, in send
    r = adapter.send(request, **kwargs)
  File "C:\Users\user\AppData\Local\Programs\Python\Python310\lib\site-packages\requests\adapters.py", line 700, in send
    raise ConnectionError(e, request=request)
requests.exceptions.ConnectionError: HTTPSConnectionPool(host='fapi.binance.com', port=443): Max retries exceeded with url: /fapi/v3/positionRisk?recvWindow=10000&symbol=ALGOUSDT&timestamp=1752353963761&signature=11a6e8d9d23f74e1e14e63989a156fae29f309db60731c994c633759bf4af6d3 (Caused by NameResolutionError("<urllib3.connection.HTTPSConnection object at 0x000001C43077C370>: Failed to resolve 'fapi.binance.com' ([Errno 11001] getaddrinfo failed)"))

Sat Jul 12 22:59:45 2025 - Erreur : Traceback (most recent call last):
  File "C:\Users\user\AppData\Local\Programs\Python\Python310\lib\site-packages\urllib3\connection.py", line 198, in _new_conn
    sock = connection.create_connection(
  File "C:\Users\user\AppData\Local\Programs\Python\Python310\lib\site-packages\urllib3\util\connection.py", line 60, in create_connection
    for res in socket.getaddrinfo(host, port, family, socket.SOCK_STREAM):
  File "C:\Users\user\AppData\Local\Programs\Python\Python310\lib\socket.py", line 955, in getaddrinfo
    for res in _socket.getaddrinfo(host, port, family, type, proto, flags):
socket.gaierror: [Errno 11001] getaddrinfo failed

The above exception was the direct cause of the following exception:

Traceback (most recent call last):
  File "C:\Users\user\AppData\Local\Programs\Python\Python310\lib\site-packages\urllib3\connectionpool.py", line 787, in urlopen
    response = self._make_request(
  File "C:\Users\user\AppData\Local\Programs\Python\Python310\lib\site-packages\urllib3\connectionpool.py", line 488, in _make_request
    raise new_e
  File "C:\Users\user\AppData\Local\Programs\Python\Python310\lib\site-packages\urllib3\connectionpool.py", line 464, in _make_request
    self._validate_conn(conn)
  File "C:\Users\user\AppData\Local\Programs\Python\Python310\lib\site-packages\urllib3\connectionpool.py", line 1093, in _validate_conn
    conn.connect()
  File "C:\Users\user\AppData\Local\Programs\Python\Python310\lib\site-packages\urllib3\connection.py", line 704, in connect
    self.sock = sock = self._new_conn()
  File "C:\Users\user\AppData\Local\Programs\Python\Python310\lib\site-packages\urllib3\connection.py", line 205, in _new_conn
    raise NameResolutionError(self.host, self, e) from e
urllib3.exceptions.NameResolutionError: <urllib3.connection.HTTPSConnection object at 0x000001C430ABCD60>: Failed to resolve 'fapi.binance.com' ([Errno 11001] getaddrinfo failed)

The above exception was the direct cause of the following exception:

Traceback (most recent call last):
  File "C:\Users\user\AppData\Local\Programs\Python\Python310\lib\site-packages\requests\adapters.py", line 667, in send
    resp = conn.urlopen(
  File "C:\Users\user\AppData\Local\Programs\Python\Python310\lib\site-packages\urllib3\connectionpool.py", line 841, in urlopen
    retries = retries.increment(
  File "C:\Users\user\AppData\Local\Programs\Python\Python310\lib\site-packages\urllib3\util\retry.py", line 519, in increment
    raise MaxRetryError(_pool, url, reason) from reason  # type: ignore[arg-type]
urllib3.exceptions.MaxRetryError: HTTPSConnectionPool(host='fapi.binance.com', port=443): Max retries exceeded with url: /fapi/v3/positionRisk?recvWindow=10000&symbol=ALGOUSDT&timestamp=1752353985010&signature=1b57b8218a30b4ea4ac52a877cd3be1da6a475a02ac0a5b25cf344a73d2a9eac (Caused by NameResolutionError("<urllib3.connection.HTTPSConnection object at 0x000001C430ABCD60>: Failed to resolve 'fapi.binance.com' ([Errno 11001] getaddrinfo failed)"))

During handling of the above exception, another exception occurred:

Traceback (most recent call last):
  File "D:\admin\MES PROJETS\Bot de trading\core\trade_executor.py", line 334, in cancel_all_open_orders_if_no_position
    positions = client.futures_position_information(symbol=symbol)
  File "C:\Users\user\AppData\Local\Programs\Python\Python310\lib\site-packages\binance\client.py", line 7835, in futures_position_information
    return self._request_futures_api("get", "positionRisk", True, 3, data=params)
  File "C:\Users\user\AppData\Local\Programs\Python\Python310\lib\site-packages\binance\client.py", line 126, in _request_futures_api
    return self._request(method, uri, signed, force_params, **kwargs)
  File "C:\Users\user\AppData\Local\Programs\Python\Python310\lib\site-packages\binance\client.py", line 88, in _request
    self.response = getattr(self.session, method)(uri, headers=headers, data=data, **kwargs)
  File "C:\Users\user\AppData\Local\Programs\Python\Python310\lib\site-packages\requests\sessions.py", line 602, in get
    return self.request("GET", url, **kwargs)
  File "C:\Users\user\AppData\Local\Programs\Python\Python310\lib\site-packages\requests\sessions.py", line 589, in request
    resp = self.send(prep, **send_kwargs)
  File "C:\Users\user\AppData\Local\Programs\Python\Python310\lib\site-packages\requests\sessions.py", line 703, in send
    r = adapter.send(request, **kwargs)
  File "C:\Users\user\AppData\Local\Programs\Python\Python310\lib\site-packages\requests\adapters.py", line 700, in send
    raise ConnectionError(e, request=request)
requests.exceptions.ConnectionError: HTTPSConnectionPool(host='fapi.binance.com', port=443): Max retries exceeded with url: /fapi/v3/positionRisk?recvWindow=10000&symbol=ALGOUSDT&timestamp=1752353985010&signature=1b57b8218a30b4ea4ac52a877cd3be1da6a475a02ac0a5b25cf344a73d2a9eac (Caused by NameResolutionError("<urllib3.connection.HTTPSConnection object at 0x000001C430ABCD60>: Failed to resolve 'fapi.binance.com' ([Errno 11001] getaddrinfo failed)"))

Sat Jul 12 22:59:55 2025 - Erreur : Traceback (most recent call last):
  File "C:\Users\user\AppData\Local\Programs\Python\Python310\lib\site-packages\urllib3\connection.py", line 198, in _new_conn
    sock = connection.create_connection(
  File "C:\Users\user\AppData\Local\Programs\Python\Python310\lib\site-packages\urllib3\util\connection.py", line 60, in create_connection
    for res in socket.getaddrinfo(host, port, family, socket.SOCK_STREAM):
  File "C:\Users\user\AppData\Local\Programs\Python\Python310\lib\socket.py", line 955, in getaddrinfo
    for res in _socket.getaddrinfo(host, port, family, type, proto, flags):
socket.gaierror: [Errno 11001] getaddrinfo failed

The above exception was the direct cause of the following exception:

Traceback (most recent call last):
  File "C:\Users\user\AppData\Local\Programs\Python\Python310\lib\site-packages\urllib3\connectionpool.py", line 787, in urlopen
    response = self._make_request(
  File "C:\Users\user\AppData\Local\Programs\Python\Python310\lib\site-packages\urllib3\connectionpool.py", line 488, in _make_request
    raise new_e
  File "C:\Users\user\AppData\Local\Programs\Python\Python310\lib\site-packages\urllib3\connectionpool.py", line 464, in _make_request
    self._validate_conn(conn)
  File "C:\Users\user\AppData\Local\Programs\Python\Python310\lib\site-packages\urllib3\connectionpool.py", line 1093, in _validate_conn
    conn.connect()
  File "C:\Users\user\AppData\Local\Programs\Python\Python310\lib\site-packages\urllib3\connection.py", line 704, in connect
    self.sock = sock = self._new_conn()
  File "C:\Users\user\AppData\Local\Programs\Python\Python310\lib\site-packages\urllib3\connection.py", line 205, in _new_conn
    raise NameResolutionError(self.host, self, e) from e
urllib3.exceptions.NameResolutionError: <urllib3.connection.HTTPSConnection object at 0x000001C430ABD120>: Failed to resolve 'fapi.binance.com' ([Errno 11001] getaddrinfo failed)

The above exception was the direct cause of the following exception:

Traceback (most recent call last):
  File "C:\Users\user\AppData\Local\Programs\Python\Python310\lib\site-packages\requests\adapters.py", line 667, in send
    resp = conn.urlopen(
  File "C:\Users\user\AppData\Local\Programs\Python\Python310\lib\site-packages\urllib3\connectionpool.py", line 841, in urlopen
    retries = retries.increment(
  File "C:\Users\user\AppData\Local\Programs\Python\Python310\lib\site-packages\urllib3\util\retry.py", line 519, in increment
    raise MaxRetryError(_pool, url, reason) from reason  # type: ignore[arg-type]
urllib3.exceptions.MaxRetryError: HTTPSConnectionPool(host='fapi.binance.com', port=443): Max retries exceeded with url: /fapi/v3/positionRisk?recvWindow=10000&symbol=ALGOUSDT&timestamp=1752353995037&signature=f9586f69ae81adedbcd417d3b1b5f01d04b90eca4e040fd9a1a2420166a2c72a (Caused by NameResolutionError("<urllib3.connection.HTTPSConnection object at 0x000001C430ABD120>: Failed to resolve 'fapi.binance.com' ([Errno 11001] getaddrinfo failed)"))

During handling of the above exception, another exception occurred:

Traceback (most recent call last):
  File "D:\admin\MES PROJETS\Bot de trading\core\trade_executor.py", line 334, in cancel_all_open_orders_if_no_position
    positions = client.futures_position_information(symbol=symbol)
  File "C:\Users\user\AppData\Local\Programs\Python\Python310\lib\site-packages\binance\client.py", line 7835, in futures_position_information
    return self._request_futures_api("get", "positionRisk", True, 3, data=params)
  File "C:\Users\user\AppData\Local\Programs\Python\Python310\lib\site-packages\binance\client.py", line 126, in _request_futures_api
    return self._request(method, uri, signed, force_params, **kwargs)
  File "C:\Users\user\AppData\Local\Programs\Python\Python310\lib\site-packages\binance\client.py", line 88, in _request
    self.response = getattr(self.session, method)(uri, headers=headers, data=data, **kwargs)
  File "C:\Users\user\AppData\Local\Programs\Python\Python310\lib\site-packages\requests\sessions.py", line 602, in get
    return self.request("GET", url, **kwargs)
  File "C:\Users\user\AppData\Local\Programs\Python\Python310\lib\site-packages\requests\sessions.py", line 589, in request
    resp = self.send(prep, **send_kwargs)
  File "C:\Users\user\AppData\Local\Programs\Python\Python310\lib\site-packages\requests\sessions.py", line 703, in send
    r = adapter.send(request, **kwargs)
  File "C:\Users\user\AppData\Local\Programs\Python\Python310\lib\site-packages\requests\adapters.py", line 700, in send
    raise ConnectionError(e, request=request)
requests.exceptions.ConnectionError: HTTPSConnectionPool(host='fapi.binance.com', port=443): Max retries exceeded with url: /fapi/v3/positionRisk?recvWindow=10000&symbol=ALGOUSDT&timestamp=1752353995037&signature=f9586f69ae81adedbcd417d3b1b5f01d04b90eca4e040fd9a1a2420166a2c72a (Caused by NameResolutionError("<urllib3.connection.HTTPSConnection object at 0x000001C430ABD120>: Failed to resolve 'fapi.binance.com' ([Errno 11001] getaddrinfo failed)"))

Sat Jul 12 23:00:05 2025 - Erreur : Traceback (most recent call last):
  File "C:\Users\user\AppData\Local\Programs\Python\Python310\lib\site-packages\urllib3\connection.py", line 198, in _new_conn
    sock = connection.create_connection(
  File "C:\Users\user\AppData\Local\Programs\Python\Python310\lib\site-packages\urllib3\util\connection.py", line 60, in create_connection
    for res in socket.getaddrinfo(host, port, family, socket.SOCK_STREAM):
  File "C:\Users\user\AppData\Local\Programs\Python\Python310\lib\socket.py", line 955, in getaddrinfo
    for res in _socket.getaddrinfo(host, port, family, type, proto, flags):
socket.gaierror: [Errno 11001] getaddrinfo failed

The above exception was the direct cause of the following exception:

Traceback (most recent call last):
  File "C:\Users\user\AppData\Local\Programs\Python\Python310\lib\site-packages\urllib3\connectionpool.py", line 787, in urlopen
    response = self._make_request(
  File "C:\Users\user\AppData\Local\Programs\Python\Python310\lib\site-packages\urllib3\connectionpool.py", line 488, in _make_request
    raise new_e
  File "C:\Users\user\AppData\Local\Programs\Python\Python310\lib\site-packages\urllib3\connectionpool.py", line 464, in _make_request
    self._validate_conn(conn)
  File "C:\Users\user\AppData\Local\Programs\Python\Python310\lib\site-packages\urllib3\connectionpool.py", line 1093, in _validate_conn
    conn.connect()
  File "C:\Users\user\AppData\Local\Programs\Python\Python310\lib\site-packages\urllib3\connection.py", line 704, in connect
    self.sock = sock = self._new_conn()
  File "C:\Users\user\AppData\Local\Programs\Python\Python310\lib\site-packages\urllib3\connection.py", line 205, in _new_conn
    raise NameResolutionError(self.host, self, e) from e
urllib3.exceptions.NameResolutionError: <urllib3.connection.HTTPSConnection object at 0x000001C430ABEE60>: Failed to resolve 'fapi.binance.com' ([Errno 11001] getaddrinfo failed)

The above exception was the direct cause of the following exception:

Traceback (most recent call last):
  File "C:\Users\user\AppData\Local\Programs\Python\Python310\lib\site-packages\requests\adapters.py", line 667, in send
    resp = conn.urlopen(
  File "C:\Users\user\AppData\Local\Programs\Python\Python310\lib\site-packages\urllib3\connectionpool.py", line 841, in urlopen
    retries = retries.increment(
  File "C:\Users\user\AppData\Local\Programs\Python\Python310\lib\site-packages\urllib3\util\retry.py", line 519, in increment
    raise MaxRetryError(_pool, url, reason) from reason  # type: ignore[arg-type]
urllib3.exceptions.MaxRetryError: HTTPSConnectionPool(host='fapi.binance.com', port=443): Max retries exceeded with url: /fapi/v3/positionRisk?recvWindow=10000&symbol=ALGOUSDT&timestamp=1752354005055&signature=6216640a147f62f3e49a282e4c896530c331a5f072d06a9e7734e70eff5d8568 (Caused by NameResolutionError("<urllib3.connection.HTTPSConnection object at 0x000001C430ABEE60>: Failed to resolve 'fapi.binance.com' ([Errno 11001] getaddrinfo failed)"))

During handling of the above exception, another exception occurred:

Traceback (most recent call last):
  File "D:\admin\MES PROJETS\Bot de trading\core\trade_executor.py", line 334, in cancel_all_open_orders_if_no_position
    positions = client.futures_position_information(symbol=symbol)
  File "C:\Users\user\AppData\Local\Programs\Python\Python310\lib\site-packages\binance\client.py", line 7835, in futures_position_information
    return self._request_futures_api("get", "positionRisk", True, 3, data=params)
  File "C:\Users\user\AppData\Local\Programs\Python\Python310\lib\site-packages\binance\client.py", line 126, in _request_futures_api
    return self._request(method, uri, signed, force_params, **kwargs)
  File "C:\Users\user\AppData\Local\Programs\Python\Python310\lib\site-packages\binance\client.py", line 88, in _request
    self.response = getattr(self.session, method)(uri, headers=headers, data=data, **kwargs)
  File "C:\Users\user\AppData\Local\Programs\Python\Python310\lib\site-packages\requests\sessions.py", line 602, in get
    return self.request("GET", url, **kwargs)
  File "C:\Users\user\AppData\Local\Programs\Python\Python310\lib\site-packages\requests\sessions.py", line 589, in request
    resp = self.send(prep, **send_kwargs)
  File "C:\Users\user\AppData\Local\Programs\Python\Python310\lib\site-packages\requests\sessions.py", line 703, in send
    r = adapter.send(request, **kwargs)
  File "C:\Users\user\AppData\Local\Programs\Python\Python310\lib\site-packages\requests\adapters.py", line 700, in send
    raise ConnectionError(e, request=request)
requests.exceptions.ConnectionError: HTTPSConnectionPool(host='fapi.binance.com', port=443): Max retries exceeded with url: /fapi/v3/positionRisk?recvWindow=10000&symbol=ALGOUSDT&timestamp=1752354005055&signature=6216640a147f62f3e49a282e4c896530c331a5f072d06a9e7734e70eff5d8568 (Caused by NameResolutionError("<urllib3.connection.HTTPSConnection object at 0x000001C430ABEE60>: Failed to resolve 'fapi.binance.com' ([Errno 11001] getaddrinfo failed)"))

Sat Jul 12 23:00:15 2025 - Erreur : Traceback (most recent call last):
  File "C:\Users\user\AppData\Local\Programs\Python\Python310\lib\site-packages\urllib3\connection.py", line 198, in _new_conn
    sock = connection.create_connection(
  File "C:\Users\user\AppData\Local\Programs\Python\Python310\lib\site-packages\urllib3\util\connection.py", line 60, in create_connection
    for res in socket.getaddrinfo(host, port, family, socket.SOCK_STREAM):
  File "C:\Users\user\AppData\Local\Programs\Python\Python310\lib\socket.py", line 955, in getaddrinfo
    for res in _socket.getaddrinfo(host, port, family, type, proto, flags):
socket.gaierror: [Errno 11001] getaddrinfo failed

The above exception was the direct cause of the following exception:

Traceback (most recent call last):
  File "C:\Users\user\AppData\Local\Programs\Python\Python310\lib\site-packages\urllib3\connectionpool.py", line 787, in urlopen
    response = self._make_request(
  File "C:\Users\user\AppData\Local\Programs\Python\Python310\lib\site-packages\urllib3\connectionpool.py", line 488, in _make_request
    raise new_e
  File "C:\Users\user\AppData\Local\Programs\Python\Python310\lib\site-packages\urllib3\connectionpool.py", line 464, in _make_request
    self._validate_conn(conn)
  File "C:\Users\user\AppData\Local\Programs\Python\Python310\lib\site-packages\urllib3\connectionpool.py", line 1093, in _validate_conn
    conn.connect()
  File "C:\Users\user\AppData\Local\Programs\Python\Python310\lib\site-packages\urllib3\connection.py", line 704, in connect
    self.sock = sock = self._new_conn()
  File "C:\Users\user\AppData\Local\Programs\Python\Python310\lib\site-packages\urllib3\connection.py", line 205, in _new_conn
    raise NameResolutionError(self.host, self, e) from e
urllib3.exceptions.NameResolutionError: <urllib3.connection.HTTPSConnection object at 0x000001C430ABFFD0>: Failed to resolve 'fapi.binance.com' ([Errno 11001] getaddrinfo failed)

The above exception was the direct cause of the following exception:

Traceback (most recent call last):
  File "C:\Users\user\AppData\Local\Programs\Python\Python310\lib\site-packages\requests\adapters.py", line 667, in send
    resp = conn.urlopen(
  File "C:\Users\user\AppData\Local\Programs\Python\Python310\lib\site-packages\urllib3\connectionpool.py", line 841, in urlopen
    retries = retries.increment(
  File "C:\Users\user\AppData\Local\Programs\Python\Python310\lib\site-packages\urllib3\util\retry.py", line 519, in increment
    raise MaxRetryError(_pool, url, reason) from reason  # type: ignore[arg-type]
urllib3.exceptions.MaxRetryError: HTTPSConnectionPool(host='fapi.binance.com', port=443): Max retries exceeded with url: /fapi/v3/positionRisk?recvWindow=10000&symbol=ALGOUSDT&timestamp=1752354015093&signature=9d53099a59822f04bb857b7253fa77dcaa1acd2cf52fd1e7064a28933e2b8b5f (Caused by NameResolutionError("<urllib3.connection.HTTPSConnection object at 0x000001C430ABFFD0>: Failed to resolve 'fapi.binance.com' ([Errno 11001] getaddrinfo failed)"))

During handling of the above exception, another exception occurred:

Traceback (most recent call last):
  File "D:\admin\MES PROJETS\Bot de trading\core\trade_executor.py", line 334, in cancel_all_open_orders_if_no_position
    positions = client.futures_position_information(symbol=symbol)
  File "C:\Users\user\AppData\Local\Programs\Python\Python310\lib\site-packages\binance\client.py", line 7835, in futures_position_information
    return self._request_futures_api("get", "positionRisk", True, 3, data=params)
  File "C:\Users\user\AppData\Local\Programs\Python\Python310\lib\site-packages\binance\client.py", line 126, in _request_futures_api
    return self._request(method, uri, signed, force_params, **kwargs)
  File "C:\Users\user\AppData\Local\Programs\Python\Python310\lib\site-packages\binance\client.py", line 88, in _request
    self.response = getattr(self.session, method)(uri, headers=headers, data=data, **kwargs)
  File "C:\Users\user\AppData\Local\Programs\Python\Python310\lib\site-packages\requests\sessions.py", line 602, in get
    return self.request("GET", url, **kwargs)
  File "C:\Users\user\AppData\Local\Programs\Python\Python310\lib\site-packages\requests\sessions.py", line 589, in request
    resp = self.send(prep, **send_kwargs)
  File "C:\Users\user\AppData\Local\Programs\Python\Python310\lib\site-packages\requests\sessions.py", line 703, in send
    r = adapter.send(request, **kwargs)
  File "C:\Users\user\AppData\Local\Programs\Python\Python310\lib\site-packages\requests\adapters.py", line 700, in send
    raise ConnectionError(e, request=request)
requests.exceptions.ConnectionError: HTTPSConnectionPool(host='fapi.binance.com', port=443): Max retries exceeded with url: /fapi/v3/positionRisk?recvWindow=10000&symbol=ALGOUSDT&timestamp=1752354015093&signature=9d53099a59822f04bb857b7253fa77dcaa1acd2cf52fd1e7064a28933e2b8b5f (Caused by NameResolutionError("<urllib3.connection.HTTPSConnection object at 0x000001C430ABFFD0>: Failed to resolve 'fapi.binance.com' ([Errno 11001] getaddrinfo failed)"))

Sat Jul 12 23:00:25 2025 - Erreur : Traceback (most recent call last):
  File "C:\Users\user\AppData\Local\Programs\Python\Python310\lib\site-packages\urllib3\connection.py", line 198, in _new_conn
    sock = connection.create_connection(
  File "C:\Users\user\AppData\Local\Programs\Python\Python310\lib\site-packages\urllib3\util\connection.py", line 60, in create_connection
    for res in socket.getaddrinfo(host, port, family, socket.SOCK_STREAM):
  File "C:\Users\user\AppData\Local\Programs\Python\Python310\lib\socket.py", line 955, in getaddrinfo
    for res in _socket.getaddrinfo(host, port, family, type, proto, flags):
socket.gaierror: [Errno 11001] getaddrinfo failed

The above exception was the direct cause of the following exception:

Traceback (most recent call last):
  File "C:\Users\user\AppData\Local\Programs\Python\Python310\lib\site-packages\urllib3\connectionpool.py", line 787, in urlopen
    response = self._make_request(
  File "C:\Users\user\AppData\Local\Programs\Python\Python310\lib\site-packages\urllib3\connectionpool.py", line 488, in _make_request
    raise new_e
  File "C:\Users\user\AppData\Local\Programs\Python\Python310\lib\site-packages\urllib3\connectionpool.py", line 464, in _make_request
    self._validate_conn(conn)
  File "C:\Users\user\AppData\Local\Programs\Python\Python310\lib\site-packages\urllib3\connectionpool.py", line 1093, in _validate_conn
    conn.connect()
  File "C:\Users\user\AppData\Local\Programs\Python\Python310\lib\site-packages\urllib3\connection.py", line 704, in connect
    self.sock = sock = self._new_conn()
  File "C:\Users\user\AppData\Local\Programs\Python\Python310\lib\site-packages\urllib3\connection.py", line 205, in _new_conn
    raise NameResolutionError(self.host, self, e) from e
urllib3.exceptions.NameResolutionError: <urllib3.connection.HTTPSConnection object at 0x000001C4306BA590>: Failed to resolve 'fapi.binance.com' ([Errno 11001] getaddrinfo failed)

The above exception was the direct cause of the following exception:

Traceback (most recent call last):
  File "C:\Users\user\AppData\Local\Programs\Python\Python310\lib\site-packages\requests\adapters.py", line 667, in send
    resp = conn.urlopen(
  File "C:\Users\user\AppData\Local\Programs\Python\Python310\lib\site-packages\urllib3\connectionpool.py", line 841, in urlopen
    retries = retries.increment(
  File "C:\Users\user\AppData\Local\Programs\Python\Python310\lib\site-packages\urllib3\util\retry.py", line 519, in increment
    raise MaxRetryError(_pool, url, reason) from reason  # type: ignore[arg-type]
urllib3.exceptions.MaxRetryError: HTTPSConnectionPool(host='fapi.binance.com', port=443): Max retries exceeded with url: /fapi/v3/positionRisk?recvWindow=10000&symbol=ALGOUSDT&timestamp=1752354025115&signature=b6a6125329c92d4275e5640f7809ec7ebef262ca94a157d8549be8006a72900d (Caused by NameResolutionError("<urllib3.connection.HTTPSConnection object at 0x000001C4306BA590>: Failed to resolve 'fapi.binance.com' ([Errno 11001] getaddrinfo failed)"))

During handling of the above exception, another exception occurred:

Traceback (most recent call last):
  File "D:\admin\MES PROJETS\Bot de trading\core\trade_executor.py", line 334, in cancel_all_open_orders_if_no_position
    positions = client.futures_position_information(symbol=symbol)
  File "C:\Users\user\AppData\Local\Programs\Python\Python310\lib\site-packages\binance\client.py", line 7835, in futures_position_information
    return self._request_futures_api("get", "positionRisk", True, 3, data=params)
  File "C:\Users\user\AppData\Local\Programs\Python\Python310\lib\site-packages\binance\client.py", line 126, in _request_futures_api
    return self._request(method, uri, signed, force_params, **kwargs)
  File "C:\Users\user\AppData\Local\Programs\Python\Python310\lib\site-packages\binance\client.py", line 88, in _request
    self.response = getattr(self.session, method)(uri, headers=headers, data=data, **kwargs)
  File "C:\Users\user\AppData\Local\Programs\Python\Python310\lib\site-packages\requests\sessions.py", line 602, in get
    return self.request("GET", url, **kwargs)
  File "C:\Users\user\AppData\Local\Programs\Python\Python310\lib\site-packages\requests\sessions.py", line 589, in request
    resp = self.send(prep, **send_kwargs)
  File "C:\Users\user\AppData\Local\Programs\Python\Python310\lib\site-packages\requests\sessions.py", line 703, in send
    r = adapter.send(request, **kwargs)
  File "C:\Users\user\AppData\Local\Programs\Python\Python310\lib\site-packages\requests\adapters.py", line 700, in send
    raise ConnectionError(e, request=request)
requests.exceptions.ConnectionError: HTTPSConnectionPool(host='fapi.binance.com', port=443): Max retries exceeded with url: /fapi/v3/positionRisk?recvWindow=10000&symbol=ALGOUSDT&timestamp=1752354025115&signature=b6a6125329c92d4275e5640f7809ec7ebef262ca94a157d8549be8006a72900d (Caused by NameResolutionError("<urllib3.connection.HTTPSConnection object at 0x000001C4306BA590>: Failed to resolve 'fapi.binance.com' ([Errno 11001] getaddrinfo failed)"))

Sat Jul 12 23:00:35 2025 - Erreur : Traceback (most recent call last):
  File "C:\Users\user\AppData\Local\Programs\Python\Python310\lib\site-packages\urllib3\connection.py", line 198, in _new_conn
    sock = connection.create_connection(
  File "C:\Users\user\AppData\Local\Programs\Python\Python310\lib\site-packages\urllib3\util\connection.py", line 60, in create_connection
    for res in socket.getaddrinfo(host, port, family, socket.SOCK_STREAM):
  File "C:\Users\user\AppData\Local\Programs\Python\Python310\lib\socket.py", line 955, in getaddrinfo
    for res in _socket.getaddrinfo(host, port, family, type, proto, flags):
socket.gaierror: [Errno 11001] getaddrinfo failed

The above exception was the direct cause of the following exception:

Traceback (most recent call last):
  File "C:\Users\user\AppData\Local\Programs\Python\Python310\lib\site-packages\urllib3\connectionpool.py", line 787, in urlopen
    response = self._make_request(
  File "C:\Users\user\AppData\Local\Programs\Python\Python310\lib\site-packages\urllib3\connectionpool.py", line 488, in _make_request
    raise new_e
  File "C:\Users\user\AppData\Local\Programs\Python\Python310\lib\site-packages\urllib3\connectionpool.py", line 464, in _make_request
    self._validate_conn(conn)
  File "C:\Users\user\AppData\Local\Programs\Python\Python310\lib\site-packages\urllib3\connectionpool.py", line 1093, in _validate_conn
    conn.connect()
  File "C:\Users\user\AppData\Local\Programs\Python\Python310\lib\site-packages\urllib3\connection.py", line 704, in connect
    self.sock = sock = self._new_conn()
  File "C:\Users\user\AppData\Local\Programs\Python\Python310\lib\site-packages\urllib3\connection.py", line 205, in _new_conn
    raise NameResolutionError(self.host, self, e) from e
urllib3.exceptions.NameResolutionError: <urllib3.connection.HTTPSConnection object at 0x000001C430AEF8E0>: Failed to resolve 'fapi.binance.com' ([Errno 11001] getaddrinfo failed)

The above exception was the direct cause of the following exception:

Traceback (most recent call last):
  File "C:\Users\user\AppData\Local\Programs\Python\Python310\lib\site-packages\requests\adapters.py", line 667, in send
    resp = conn.urlopen(
  File "C:\Users\user\AppData\Local\Programs\Python\Python310\lib\site-packages\urllib3\connectionpool.py", line 841, in urlopen
    retries = retries.increment(
  File "C:\Users\user\AppData\Local\Programs\Python\Python310\lib\site-packages\urllib3\util\retry.py", line 519, in increment
    raise MaxRetryError(_pool, url, reason) from reason  # type: ignore[arg-type]
urllib3.exceptions.MaxRetryError: HTTPSConnectionPool(host='fapi.binance.com', port=443): Max retries exceeded with url: /fapi/v3/positionRisk?recvWindow=10000&symbol=ALGOUSDT&timestamp=1752354035130&signature=6037d9f90ee2918b59525100107ed41c24b0bbea8514c04abc698595a946715d (Caused by NameResolutionError("<urllib3.connection.HTTPSConnection object at 0x000001C430AEF8E0>: Failed to resolve 'fapi.binance.com' ([Errno 11001] getaddrinfo failed)"))

During handling of the above exception, another exception occurred:

Traceback (most recent call last):
  File "D:\admin\MES PROJETS\Bot de trading\core\trade_executor.py", line 334, in cancel_all_open_orders_if_no_position
    positions = client.futures_position_information(symbol=symbol)
  File "C:\Users\user\AppData\Local\Programs\Python\Python310\lib\site-packages\binance\client.py", line 7835, in futures_position_information
    return self._request_futures_api("get", "positionRisk", True, 3, data=params)
  File "C:\Users\user\AppData\Local\Programs\Python\Python310\lib\site-packages\binance\client.py", line 126, in _request_futures_api
    return self._request(method, uri, signed, force_params, **kwargs)
  File "C:\Users\user\AppData\Local\Programs\Python\Python310\lib\site-packages\binance\client.py", line 88, in _request
    self.response = getattr(self.session, method)(uri, headers=headers, data=data, **kwargs)
  File "C:\Users\user\AppData\Local\Programs\Python\Python310\lib\site-packages\requests\sessions.py", line 602, in get
    return self.request("GET", url, **kwargs)
  File "C:\Users\user\AppData\Local\Programs\Python\Python310\lib\site-packages\requests\sessions.py", line 589, in request
    resp = self.send(prep, **send_kwargs)
  File "C:\Users\user\AppData\Local\Programs\Python\Python310\lib\site-packages\requests\sessions.py", line 703, in send
    r = adapter.send(request, **kwargs)
  File "C:\Users\user\AppData\Local\Programs\Python\Python310\lib\site-packages\requests\adapters.py", line 700, in send
    raise ConnectionError(e, request=request)
requests.exceptions.ConnectionError: HTTPSConnectionPool(host='fapi.binance.com', port=443): Max retries exceeded with url: /fapi/v3/positionRisk?recvWindow=10000&symbol=ALGOUSDT&timestamp=1752354035130&signature=6037d9f90ee2918b59525100107ed41c24b0bbea8514c04abc698595a946715d (Caused by NameResolutionError("<urllib3.connection.HTTPSConnection object at 0x000001C430AEF8E0>: Failed to resolve 'fapi.binance.com' ([Errno 11001] getaddrinfo failed)"))

Sat Jul 12 23:00:45 2025 - Erreur : Traceback (most recent call last):
  File "C:\Users\user\AppData\Local\Programs\Python\Python310\lib\site-packages\urllib3\connection.py", line 198, in _new_conn
    sock = connection.create_connection(
  File "C:\Users\user\AppData\Local\Programs\Python\Python310\lib\site-packages\urllib3\util\connection.py", line 60, in create_connection
    for res in socket.getaddrinfo(host, port, family, socket.SOCK_STREAM):
  File "C:\Users\user\AppData\Local\Programs\Python\Python310\lib\socket.py", line 955, in getaddrinfo
    for res in _socket.getaddrinfo(host, port, family, type, proto, flags):
socket.gaierror: [Errno 11001] getaddrinfo failed

The above exception was the direct cause of the following exception:

Traceback (most recent call last):
  File "C:\Users\user\AppData\Local\Programs\Python\Python310\lib\site-packages\urllib3\connectionpool.py", line 787, in urlopen
    response = self._make_request(
  File "C:\Users\user\AppData\Local\Programs\Python\Python310\lib\site-packages\urllib3\connectionpool.py", line 488, in _make_request
    raise new_e
  File "C:\Users\user\AppData\Local\Programs\Python\Python310\lib\site-packages\urllib3\connectionpool.py", line 464, in _make_request
    self._validate_conn(conn)
  File "C:\Users\user\AppData\Local\Programs\Python\Python310\lib\site-packages\urllib3\connectionpool.py", line 1093, in _validate_conn
    conn.connect()
  File "C:\Users\user\AppData\Local\Programs\Python\Python310\lib\site-packages\urllib3\connection.py", line 704, in connect
    self.sock = sock = self._new_conn()
  File "C:\Users\user\AppData\Local\Programs\Python\Python310\lib\site-packages\urllib3\connection.py", line 205, in _new_conn
    raise NameResolutionError(self.host, self, e) from e
urllib3.exceptions.NameResolutionError: <urllib3.connection.HTTPSConnection object at 0x000001C430AFF070>: Failed to resolve 'fapi.binance.com' ([Errno 11001] getaddrinfo failed)

The above exception was the direct cause of the following exception:

Traceback (most recent call last):
  File "C:\Users\user\AppData\Local\Programs\Python\Python310\lib\site-packages\requests\adapters.py", line 667, in send
    resp = conn.urlopen(
  File "C:\Users\user\AppData\Local\Programs\Python\Python310\lib\site-packages\urllib3\connectionpool.py", line 841, in urlopen
    retries = retries.increment(
  File "C:\Users\user\AppData\Local\Programs\Python\Python310\lib\site-packages\urllib3\util\retry.py", line 519, in increment
    raise MaxRetryError(_pool, url, reason) from reason  # type: ignore[arg-type]
urllib3.exceptions.MaxRetryError: HTTPSConnectionPool(host='fapi.binance.com', port=443): Max retries exceeded with url: /fapi/v3/positionRisk?recvWindow=10000&symbol=ALGOUSDT&timestamp=1752354045145&signature=4073daa365b7f4e0f6fec09d6a73eba7df5755df72c7dad43b26bbae1580c005 (Caused by NameResolutionError("<urllib3.connection.HTTPSConnection object at 0x000001C430AFF070>: Failed to resolve 'fapi.binance.com' ([Errno 11001] getaddrinfo failed)"))

During handling of the above exception, another exception occurred:

Traceback (most recent call last):
  File "D:\admin\MES PROJETS\Bot de trading\core\trade_executor.py", line 334, in cancel_all_open_orders_if_no_position
    positions = client.futures_position_information(symbol=symbol)
  File "C:\Users\user\AppData\Local\Programs\Python\Python310\lib\site-packages\binance\client.py", line 7835, in futures_position_information
    return self._request_futures_api("get", "positionRisk", True, 3, data=params)
  File "C:\Users\user\AppData\Local\Programs\Python\Python310\lib\site-packages\binance\client.py", line 126, in _request_futures_api
    return self._request(method, uri, signed, force_params, **kwargs)
  File "C:\Users\user\AppData\Local\Programs\Python\Python310\lib\site-packages\binance\client.py", line 88, in _request
    self.response = getattr(self.session, method)(uri, headers=headers, data=data, **kwargs)
  File "C:\Users\user\AppData\Local\Programs\Python\Python310\lib\site-packages\requests\sessions.py", line 602, in get
    return self.request("GET", url, **kwargs)
  File "C:\Users\user\AppData\Local\Programs\Python\Python310\lib\site-packages\requests\sessions.py", line 589, in request
    resp = self.send(prep, **send_kwargs)
  File "C:\Users\user\AppData\Local\Programs\Python\Python310\lib\site-packages\requests\sessions.py", line 703, in send
    r = adapter.send(request, **kwargs)
  File "C:\Users\user\AppData\Local\Programs\Python\Python310\lib\site-packages\requests\adapters.py", line 700, in send
    raise ConnectionError(e, request=request)
requests.exceptions.ConnectionError: HTTPSConnectionPool(host='fapi.binance.com', port=443): Max retries exceeded with url: /fapi/v3/positionRisk?recvWindow=10000&symbol=ALGOUSDT&timestamp=1752354045145&signature=4073daa365b7f4e0f6fec09d6a73eba7df5755df72c7dad43b26bbae1580c005 (Caused by NameResolutionError("<urllib3.connection.HTTPSConnection object at 0x000001C430AFF070>: Failed to resolve 'fapi.binance.com' ([Errno 11001] getaddrinfo failed)"))

Sat Jul 12 23:00:55 2025 - Erreur : Traceback (most recent call last):
  File "C:\Users\user\AppData\Local\Programs\Python\Python310\lib\site-packages\urllib3\connection.py", line 198, in _new_conn
    sock = connection.create_connection(
  File "C:\Users\user\AppData\Local\Programs\Python\Python310\lib\site-packages\urllib3\util\connection.py", line 60, in create_connection
    for res in socket.getaddrinfo(host, port, family, socket.SOCK_STREAM):
  File "C:\Users\user\AppData\Local\Programs\Python\Python310\lib\socket.py", line 955, in getaddrinfo
    for res in _socket.getaddrinfo(host, port, family, type, proto, flags):
socket.gaierror: [Errno 11001] getaddrinfo failed

The above exception was the direct cause of the following exception:

Traceback (most recent call last):
  File "C:\Users\user\AppData\Local\Programs\Python\Python310\lib\site-packages\urllib3\connectionpool.py", line 787, in urlopen
    response = self._make_request(
  File "C:\Users\user\AppData\Local\Programs\Python\Python310\lib\site-packages\urllib3\connectionpool.py", line 488, in _make_request
    raise new_e
  File "C:\Users\user\AppData\Local\Programs\Python\Python310\lib\site-packages\urllib3\connectionpool.py", line 464, in _make_request
    self._validate_conn(conn)
  File "C:\Users\user\AppData\Local\Programs\Python\Python310\lib\site-packages\urllib3\connectionpool.py", line 1093, in _validate_conn
    conn.connect()
  File "C:\Users\user\AppData\Local\Programs\Python\Python310\lib\site-packages\urllib3\connection.py", line 704, in connect
    self.sock = sock = self._new_conn()
  File "C:\Users\user\AppData\Local\Programs\Python\Python310\lib\site-packages\urllib3\connection.py", line 205, in _new_conn
    raise NameResolutionError(self.host, self, e) from e
urllib3.exceptions.NameResolutionError: <urllib3.connection.HTTPSConnection object at 0x000001C43077E920>: Failed to resolve 'fapi.binance.com' ([Errno 11001] getaddrinfo failed)

The above exception was the direct cause of the following exception:

Traceback (most recent call last):
  File "C:\Users\user\AppData\Local\Programs\Python\Python310\lib\site-packages\requests\adapters.py", line 667, in send
    resp = conn.urlopen(
  File "C:\Users\user\AppData\Local\Programs\Python\Python310\lib\site-packages\urllib3\connectionpool.py", line 841, in urlopen
    retries = retries.increment(
  File "C:\Users\user\AppData\Local\Programs\Python\Python310\lib\site-packages\urllib3\util\retry.py", line 519, in increment
    raise MaxRetryError(_pool, url, reason) from reason  # type: ignore[arg-type]
urllib3.exceptions.MaxRetryError: HTTPSConnectionPool(host='fapi.binance.com', port=443): Max retries exceeded with url: /fapi/v3/positionRisk?recvWindow=10000&symbol=ALGOUSDT&timestamp=1752354055158&signature=d5405f229063db4b8a9a50844239260d8f137935e3b821a198e1122180c196a3 (Caused by NameResolutionError("<urllib3.connection.HTTPSConnection object at 0x000001C43077E920>: Failed to resolve 'fapi.binance.com' ([Errno 11001] getaddrinfo failed)"))

During handling of the above exception, another exception occurred:

Traceback (most recent call last):
  File "D:\admin\MES PROJETS\Bot de trading\core\trade_executor.py", line 334, in cancel_all_open_orders_if_no_position
    positions = client.futures_position_information(symbol=symbol)
  File "C:\Users\user\AppData\Local\Programs\Python\Python310\lib\site-packages\binance\client.py", line 7835, in futures_position_information
    return self._request_futures_api("get", "positionRisk", True, 3, data=params)
  File "C:\Users\user\AppData\Local\Programs\Python\Python310\lib\site-packages\binance\client.py", line 126, in _request_futures_api
    return self._request(method, uri, signed, force_params, **kwargs)
  File "C:\Users\user\AppData\Local\Programs\Python\Python310\lib\site-packages\binance\client.py", line 88, in _request
    self.response = getattr(self.session, method)(uri, headers=headers, data=data, **kwargs)
  File "C:\Users\user\AppData\Local\Programs\Python\Python310\lib\site-packages\requests\sessions.py", line 602, in get
    return self.request("GET", url, **kwargs)
  File "C:\Users\user\AppData\Local\Programs\Python\Python310\lib\site-packages\requests\sessions.py", line 589, in request
    resp = self.send(prep, **send_kwargs)
  File "C:\Users\user\AppData\Local\Programs\Python\Python310\lib\site-packages\requests\sessions.py", line 703, in send
    r = adapter.send(request, **kwargs)
  File "C:\Users\user\AppData\Local\Programs\Python\Python310\lib\site-packages\requests\adapters.py", line 700, in send
    raise ConnectionError(e, request=request)
requests.exceptions.ConnectionError: HTTPSConnectionPool(host='fapi.binance.com', port=443): Max retries exceeded with url: /fapi/v3/positionRisk?recvWindow=10000&symbol=ALGOUSDT&timestamp=1752354055158&signature=d5405f229063db4b8a9a50844239260d8f137935e3b821a198e1122180c196a3 (Caused by NameResolutionError("<urllib3.connection.HTTPSConnection object at 0x000001C43077E920>: Failed to resolve 'fapi.binance.com' ([Errno 11001] getaddrinfo failed)"))

Sat Jul 12 23:01:05 2025 - Erreur : Traceback (most recent call last):
  File "C:\Users\user\AppData\Local\Programs\Python\Python310\lib\site-packages\urllib3\connection.py", line 198, in _new_conn
    sock = connection.create_connection(
  File "C:\Users\user\AppData\Local\Programs\Python\Python310\lib\site-packages\urllib3\util\connection.py", line 60, in create_connection
    for res in socket.getaddrinfo(host, port, family, socket.SOCK_STREAM):
  File "C:\Users\user\AppData\Local\Programs\Python\Python310\lib\socket.py", line 955, in getaddrinfo
    for res in _socket.getaddrinfo(host, port, family, type, proto, flags):
socket.gaierror: [Errno 11001] getaddrinfo failed

The above exception was the direct cause of the following exception:

Traceback (most recent call last):
  File "C:\Users\user\AppData\Local\Programs\Python\Python310\lib\site-packages\urllib3\connectionpool.py", line 787, in urlopen
    response = self._make_request(
  File "C:\Users\user\AppData\Local\Programs\Python\Python310\lib\site-packages\urllib3\connectionpool.py", line 488, in _make_request
    raise new_e
  File "C:\Users\user\AppData\Local\Programs\Python\Python310\lib\site-packages\urllib3\connectionpool.py", line 464, in _make_request
    self._validate_conn(conn)
  File "C:\Users\user\AppData\Local\Programs\Python\Python310\lib\site-packages\urllib3\connectionpool.py", line 1093, in _validate_conn
    conn.connect()
  File "C:\Users\user\AppData\Local\Programs\Python\Python310\lib\site-packages\urllib3\connection.py", line 704, in connect
    self.sock = sock = self._new_conn()
  File "C:\Users\user\AppData\Local\Programs\Python\Python310\lib\site-packages\urllib3\connection.py", line 205, in _new_conn
    raise NameResolutionError(self.host, self, e) from e
urllib3.exceptions.NameResolutionError: <urllib3.connection.HTTPSConnection object at 0x000001C430B28610>: Failed to resolve 'fapi.binance.com' ([Errno 11001] getaddrinfo failed)

The above exception was the direct cause of the following exception:

Traceback (most recent call last):
  File "C:\Users\user\AppData\Local\Programs\Python\Python310\lib\site-packages\requests\adapters.py", line 667, in send
    resp = conn.urlopen(
  File "C:\Users\user\AppData\Local\Programs\Python\Python310\lib\site-packages\urllib3\connectionpool.py", line 841, in urlopen
    retries = retries.increment(
  File "C:\Users\user\AppData\Local\Programs\Python\Python310\lib\site-packages\urllib3\util\retry.py", line 519, in increment
    raise MaxRetryError(_pool, url, reason) from reason  # type: ignore[arg-type]
urllib3.exceptions.MaxRetryError: HTTPSConnectionPool(host='fapi.binance.com', port=443): Max retries exceeded with url: /fapi/v3/positionRisk?recvWindow=10000&symbol=ALGOUSDT&timestamp=1752354065178&signature=d0e440b4274083a398d69e5f294afa7cb42b13a8b688d6e20d4fdc661d939ccd (Caused by NameResolutionError("<urllib3.connection.HTTPSConnection object at 0x000001C430B28610>: Failed to resolve 'fapi.binance.com' ([Errno 11001] getaddrinfo failed)"))

During handling of the above exception, another exception occurred:

Traceback (most recent call last):
  File "D:\admin\MES PROJETS\Bot de trading\core\trade_executor.py", line 334, in cancel_all_open_orders_if_no_position
    positions = client.futures_position_information(symbol=symbol)
  File "C:\Users\user\AppData\Local\Programs\Python\Python310\lib\site-packages\binance\client.py", line 7835, in futures_position_information
    return self._request_futures_api("get", "positionRisk", True, 3, data=params)
  File "C:\Users\user\AppData\Local\Programs\Python\Python310\lib\site-packages\binance\client.py", line 126, in _request_futures_api
    return self._request(method, uri, signed, force_params, **kwargs)
  File "C:\Users\user\AppData\Local\Programs\Python\Python310\lib\site-packages\binance\client.py", line 88, in _request
    self.response = getattr(self.session, method)(uri, headers=headers, data=data, **kwargs)
  File "C:\Users\user\AppData\Local\Programs\Python\Python310\lib\site-packages\requests\sessions.py", line 602, in get
    return self.request("GET", url, **kwargs)
  File "C:\Users\user\AppData\Local\Programs\Python\Python310\lib\site-packages\requests\sessions.py", line 589, in request
    resp = self.send(prep, **send_kwargs)
  File "C:\Users\user\AppData\Local\Programs\Python\Python310\lib\site-packages\requests\sessions.py", line 703, in send
    r = adapter.send(request, **kwargs)
  File "C:\Users\user\AppData\Local\Programs\Python\Python310\lib\site-packages\requests\adapters.py", line 700, in send
    raise ConnectionError(e, request=request)
requests.exceptions.ConnectionError: HTTPSConnectionPool(host='fapi.binance.com', port=443): Max retries exceeded with url: /fapi/v3/positionRisk?recvWindow=10000&symbol=ALGOUSDT&timestamp=1752354065178&signature=d0e440b4274083a398d69e5f294afa7cb42b13a8b688d6e20d4fdc661d939ccd (Caused by NameResolutionError("<urllib3.connection.HTTPSConnection object at 0x000001C430B28610>: Failed to resolve 'fapi.binance.com' ([Errno 11001] getaddrinfo failed)"))

Sat Jul 12 23:01:15 2025 - Erreur : Traceback (most recent call last):
  File "C:\Users\user\AppData\Local\Programs\Python\Python310\lib\site-packages\urllib3\connection.py", line 198, in _new_conn
    sock = connection.create_connection(
  File "C:\Users\user\AppData\Local\Programs\Python\Python310\lib\site-packages\urllib3\util\connection.py", line 60, in create_connection
    for res in socket.getaddrinfo(host, port, family, socket.SOCK_STREAM):
  File "C:\Users\user\AppData\Local\Programs\Python\Python310\lib\socket.py", line 955, in getaddrinfo
    for res in _socket.getaddrinfo(host, port, family, type, proto, flags):
socket.gaierror: [Errno 11001] getaddrinfo failed

The above exception was the direct cause of the following exception:

Traceback (most recent call last):
  File "C:\Users\user\AppData\Local\Programs\Python\Python310\lib\site-packages\urllib3\connectionpool.py", line 787, in urlopen
    response = self._make_request(
  File "C:\Users\user\AppData\Local\Programs\Python\Python310\lib\site-packages\urllib3\connectionpool.py", line 488, in _make_request
    raise new_e
  File "C:\Users\user\AppData\Local\Programs\Python\Python310\lib\site-packages\urllib3\connectionpool.py", line 464, in _make_request
    self._validate_conn(conn)
  File "C:\Users\user\AppData\Local\Programs\Python\Python310\lib\site-packages\urllib3\connectionpool.py", line 1093, in _validate_conn
    conn.connect()
  File "C:\Users\user\AppData\Local\Programs\Python\Python310\lib\site-packages\urllib3\connection.py", line 704, in connect
    self.sock = sock = self._new_conn()
  File "C:\Users\user\AppData\Local\Programs\Python\Python310\lib\site-packages\urllib3\connection.py", line 205, in _new_conn
    raise NameResolutionError(self.host, self, e) from e
urllib3.exceptions.NameResolutionError: <urllib3.connection.HTTPSConnection object at 0x000001C430B28370>: Failed to resolve 'fapi.binance.com' ([Errno 11001] getaddrinfo failed)

The above exception was the direct cause of the following exception:

Traceback (most recent call last):
  File "C:\Users\user\AppData\Local\Programs\Python\Python310\lib\site-packages\requests\adapters.py", line 667, in send
    resp = conn.urlopen(
  File "C:\Users\user\AppData\Local\Programs\Python\Python310\lib\site-packages\urllib3\connectionpool.py", line 841, in urlopen
    retries = retries.increment(
  File "C:\Users\user\AppData\Local\Programs\Python\Python310\lib\site-packages\urllib3\util\retry.py", line 519, in increment
    raise MaxRetryError(_pool, url, reason) from reason  # type: ignore[arg-type]
urllib3.exceptions.MaxRetryError: HTTPSConnectionPool(host='fapi.binance.com', port=443): Max retries exceeded with url: /fapi/v3/positionRisk?recvWindow=10000&symbol=ALGOUSDT&timestamp=1752354075211&signature=99ac068106d688a2e63a6a3e83ea50436b82117804de597f5074681ccaec85c3 (Caused by NameResolutionError("<urllib3.connection.HTTPSConnection object at 0x000001C430B28370>: Failed to resolve 'fapi.binance.com' ([Errno 11001] getaddrinfo failed)"))

During handling of the above exception, another exception occurred:

Traceback (most recent call last):
  File "D:\admin\MES PROJETS\Bot de trading\core\trade_executor.py", line 334, in cancel_all_open_orders_if_no_position
    positions = client.futures_position_information(symbol=symbol)
  File "C:\Users\user\AppData\Local\Programs\Python\Python310\lib\site-packages\binance\client.py", line 7835, in futures_position_information
    return self._request_futures_api("get", "positionRisk", True, 3, data=params)
  File "C:\Users\user\AppData\Local\Programs\Python\Python310\lib\site-packages\binance\client.py", line 126, in _request_futures_api
    return self._request(method, uri, signed, force_params, **kwargs)
  File "C:\Users\user\AppData\Local\Programs\Python\Python310\lib\site-packages\binance\client.py", line 88, in _request
    self.response = getattr(self.session, method)(uri, headers=headers, data=data, **kwargs)
  File "C:\Users\user\AppData\Local\Programs\Python\Python310\lib\site-packages\requests\sessions.py", line 602, in get
    return self.request("GET", url, **kwargs)
  File "C:\Users\user\AppData\Local\Programs\Python\Python310\lib\site-packages\requests\sessions.py", line 589, in request
    resp = self.send(prep, **send_kwargs)
  File "C:\Users\user\AppData\Local\Programs\Python\Python310\lib\site-packages\requests\sessions.py", line 703, in send
    r = adapter.send(request, **kwargs)
  File "C:\Users\user\AppData\Local\Programs\Python\Python310\lib\site-packages\requests\adapters.py", line 700, in send
    raise ConnectionError(e, request=request)
requests.exceptions.ConnectionError: HTTPSConnectionPool(host='fapi.binance.com', port=443): Max retries exceeded with url: /fapi/v3/positionRisk?recvWindow=10000&symbol=ALGOUSDT&timestamp=1752354075211&signature=99ac068106d688a2e63a6a3e83ea50436b82117804de597f5074681ccaec85c3 (Caused by NameResolutionError("<urllib3.connection.HTTPSConnection object at 0x000001C430B28370>: Failed to resolve 'fapi.binance.com' ([Errno 11001] getaddrinfo failed)"))

Sat Jul 12 23:01:25 2025 - Erreur : Traceback (most recent call last):
  File "C:\Users\user\AppData\Local\Programs\Python\Python310\lib\site-packages\urllib3\connection.py", line 198, in _new_conn
    sock = connection.create_connection(
  File "C:\Users\user\AppData\Local\Programs\Python\Python310\lib\site-packages\urllib3\util\connection.py", line 60, in create_connection
    for res in socket.getaddrinfo(host, port, family, socket.SOCK_STREAM):
  File "C:\Users\user\AppData\Local\Programs\Python\Python310\lib\socket.py", line 955, in getaddrinfo
    for res in _socket.getaddrinfo(host, port, family, type, proto, flags):
socket.gaierror: [Errno 11001] getaddrinfo failed

The above exception was the direct cause of the following exception:

Traceback (most recent call last):
  File "C:\Users\user\AppData\Local\Programs\Python\Python310\lib\site-packages\urllib3\connectionpool.py", line 787, in urlopen
    response = self._make_request(
  File "C:\Users\user\AppData\Local\Programs\Python\Python310\lib\site-packages\urllib3\connectionpool.py", line 488, in _make_request
    raise new_e
  File "C:\Users\user\AppData\Local\Programs\Python\Python310\lib\site-packages\urllib3\connectionpool.py", line 464, in _make_request
    self._validate_conn(conn)
  File "C:\Users\user\AppData\Local\Programs\Python\Python310\lib\site-packages\urllib3\connectionpool.py", line 1093, in _validate_conn
    conn.connect()
  File "C:\Users\user\AppData\Local\Programs\Python\Python310\lib\site-packages\urllib3\connection.py", line 704, in connect
    self.sock = sock = self._new_conn()
  File "C:\Users\user\AppData\Local\Programs\Python\Python310\lib\site-packages\urllib3\connection.py", line 205, in _new_conn
    raise NameResolutionError(self.host, self, e) from e
urllib3.exceptions.NameResolutionError: <urllib3.connection.HTTPSConnection object at 0x000001C430AFE200>: Failed to resolve 'fapi.binance.com' ([Errno 11001] getaddrinfo failed)

The above exception was the direct cause of the following exception:

Traceback (most recent call last):
  File "C:\Users\user\AppData\Local\Programs\Python\Python310\lib\site-packages\requests\adapters.py", line 667, in send
    resp = conn.urlopen(
  File "C:\Users\user\AppData\Local\Programs\Python\Python310\lib\site-packages\urllib3\connectionpool.py", line 841, in urlopen
    retries = retries.increment(
  File "C:\Users\user\AppData\Local\Programs\Python\Python310\lib\site-packages\urllib3\util\retry.py", line 519, in increment
    raise MaxRetryError(_pool, url, reason) from reason  # type: ignore[arg-type]
urllib3.exceptions.MaxRetryError: HTTPSConnectionPool(host='fapi.binance.com', port=443): Max retries exceeded with url: /fapi/v3/positionRisk?recvWindow=10000&symbol=ALGOUSDT&timestamp=1752354085217&signature=e4b0d93af1e1249b711c7e49f9ab0730e4b73f7a1d61e24effdc3db5c0feff4a (Caused by NameResolutionError("<urllib3.connection.HTTPSConnection object at 0x000001C430AFE200>: Failed to resolve 'fapi.binance.com' ([Errno 11001] getaddrinfo failed)"))

During handling of the above exception, another exception occurred:

Traceback (most recent call last):
  File "D:\admin\MES PROJETS\Bot de trading\core\trade_executor.py", line 334, in cancel_all_open_orders_if_no_position
    positions = client.futures_position_information(symbol=symbol)
  File "C:\Users\user\AppData\Local\Programs\Python\Python310\lib\site-packages\binance\client.py", line 7835, in futures_position_information
    return self._request_futures_api("get", "positionRisk", True, 3, data=params)
  File "C:\Users\user\AppData\Local\Programs\Python\Python310\lib\site-packages\binance\client.py", line 126, in _request_futures_api
    return self._request(method, uri, signed, force_params, **kwargs)
  File "C:\Users\user\AppData\Local\Programs\Python\Python310\lib\site-packages\binance\client.py", line 88, in _request
    self.response = getattr(self.session, method)(uri, headers=headers, data=data, **kwargs)
  File "C:\Users\user\AppData\Local\Programs\Python\Python310\lib\site-packages\requests\sessions.py", line 602, in get
    return self.request("GET", url, **kwargs)
  File "C:\Users\user\AppData\Local\Programs\Python\Python310\lib\site-packages\requests\sessions.py", line 589, in request
    resp = self.send(prep, **send_kwargs)
  File "C:\Users\user\AppData\Local\Programs\Python\Python310\lib\site-packages\requests\sessions.py", line 703, in send
    r = adapter.send(request, **kwargs)
  File "C:\Users\user\AppData\Local\Programs\Python\Python310\lib\site-packages\requests\adapters.py", line 700, in send
    raise ConnectionError(e, request=request)
requests.exceptions.ConnectionError: HTTPSConnectionPool(host='fapi.binance.com', port=443): Max retries exceeded with url: /fapi/v3/positionRisk?recvWindow=10000&symbol=ALGOUSDT&timestamp=1752354085217&signature=e4b0d93af1e1249b711c7e49f9ab0730e4b73f7a1d61e24effdc3db5c0feff4a (Caused by NameResolutionError("<urllib3.connection.HTTPSConnection object at 0x000001C430AFE200>: Failed to resolve 'fapi.binance.com' ([Errno 11001] getaddrinfo failed)"))

Sat Jul 12 23:01:35 2025 - Erreur : Traceback (most recent call last):
  File "C:\Users\user\AppData\Local\Programs\Python\Python310\lib\site-packages\urllib3\connection.py", line 198, in _new_conn
    sock = connection.create_connection(
  File "C:\Users\user\AppData\Local\Programs\Python\Python310\lib\site-packages\urllib3\util\connection.py", line 60, in create_connection
    for res in socket.getaddrinfo(host, port, family, socket.SOCK_STREAM):
  File "C:\Users\user\AppData\Local\Programs\Python\Python310\lib\socket.py", line 955, in getaddrinfo
    for res in _socket.getaddrinfo(host, port, family, type, proto, flags):
socket.gaierror: [Errno 11001] getaddrinfo failed

The above exception was the direct cause of the following exception:

Traceback (most recent call last):
  File "C:\Users\user\AppData\Local\Programs\Python\Python310\lib\site-packages\urllib3\connectionpool.py", line 787, in urlopen
    response = self._make_request(
  File "C:\Users\user\AppData\Local\Programs\Python\Python310\lib\site-packages\urllib3\connectionpool.py", line 488, in _make_request
    raise new_e
  File "C:\Users\user\AppData\Local\Programs\Python\Python310\lib\site-packages\urllib3\connectionpool.py", line 464, in _make_request
    self._validate_conn(conn)
  File "C:\Users\user\AppData\Local\Programs\Python\Python310\lib\site-packages\urllib3\connectionpool.py", line 1093, in _validate_conn
    conn.connect()
  File "C:\Users\user\AppData\Local\Programs\Python\Python310\lib\site-packages\urllib3\connection.py", line 704, in connect
    self.sock = sock = self._new_conn()
  File "C:\Users\user\AppData\Local\Programs\Python\Python310\lib\site-packages\urllib3\connection.py", line 205, in _new_conn
    raise NameResolutionError(self.host, self, e) from e
urllib3.exceptions.NameResolutionError: <urllib3.connection.HTTPSConnection object at 0x000001C430AEE410>: Failed to resolve 'fapi.binance.com' ([Errno 11001] getaddrinfo failed)

The above exception was the direct cause of the following exception:

Traceback (most recent call last):
  File "C:\Users\user\AppData\Local\Programs\Python\Python310\lib\site-packages\requests\adapters.py", line 667, in send
    resp = conn.urlopen(
  File "C:\Users\user\AppData\Local\Programs\Python\Python310\lib\site-packages\urllib3\connectionpool.py", line 841, in urlopen
    retries = retries.increment(
  File "C:\Users\user\AppData\Local\Programs\Python\Python310\lib\site-packages\urllib3\util\retry.py", line 519, in increment
    raise MaxRetryError(_pool, url, reason) from reason  # type: ignore[arg-type]
urllib3.exceptions.MaxRetryError: HTTPSConnectionPool(host='fapi.binance.com', port=443): Max retries exceeded with url: /fapi/v3/positionRisk?recvWindow=10000&symbol=ALGOUSDT&timestamp=1752354095251&signature=070e1b80689f2220def4c33a16547fad4c2901a0b060918f8e4c6edd2a2e6131 (Caused by NameResolutionError("<urllib3.connection.HTTPSConnection object at 0x000001C430AEE410>: Failed to resolve 'fapi.binance.com' ([Errno 11001] getaddrinfo failed)"))

During handling of the above exception, another exception occurred:

Traceback (most recent call last):
  File "D:\admin\MES PROJETS\Bot de trading\core\trade_executor.py", line 334, in cancel_all_open_orders_if_no_position
    positions = client.futures_position_information(symbol=symbol)
  File "C:\Users\user\AppData\Local\Programs\Python\Python310\lib\site-packages\binance\client.py", line 7835, in futures_position_information
    return self._request_futures_api("get", "positionRisk", True, 3, data=params)
  File "C:\Users\user\AppData\Local\Programs\Python\Python310\lib\site-packages\binance\client.py", line 126, in _request_futures_api
    return self._request(method, uri, signed, force_params, **kwargs)
  File "C:\Users\user\AppData\Local\Programs\Python\Python310\lib\site-packages\binance\client.py", line 88, in _request
    self.response = getattr(self.session, method)(uri, headers=headers, data=data, **kwargs)
  File "C:\Users\user\AppData\Local\Programs\Python\Python310\lib\site-packages\requests\sessions.py", line 602, in get
    return self.request("GET", url, **kwargs)
  File "C:\Users\user\AppData\Local\Programs\Python\Python310\lib\site-packages\requests\sessions.py", line 589, in request
    resp = self.send(prep, **send_kwargs)
  File "C:\Users\user\AppData\Local\Programs\Python\Python310\lib\site-packages\requests\sessions.py", line 703, in send
    r = adapter.send(request, **kwargs)
  File "C:\Users\user\AppData\Local\Programs\Python\Python310\lib\site-packages\requests\adapters.py", line 700, in send
    raise ConnectionError(e, request=request)
requests.exceptions.ConnectionError: HTTPSConnectionPool(host='fapi.binance.com', port=443): Max retries exceeded with url: /fapi/v3/positionRisk?recvWindow=10000&symbol=ALGOUSDT&timestamp=1752354095251&signature=070e1b80689f2220def4c33a16547fad4c2901a0b060918f8e4c6edd2a2e6131 (Caused by NameResolutionError("<urllib3.connection.HTTPSConnection object at 0x000001C430AEE410>: Failed to resolve 'fapi.binance.com' ([Errno 11001] getaddrinfo failed)"))

Sat Jul 12 23:01:45 2025 - Erreur : Traceback (most recent call last):
  File "C:\Users\user\AppData\Local\Programs\Python\Python310\lib\site-packages\urllib3\connection.py", line 198, in _new_conn
    sock = connection.create_connection(
  File "C:\Users\user\AppData\Local\Programs\Python\Python310\lib\site-packages\urllib3\util\connection.py", line 60, in create_connection
    for res in socket.getaddrinfo(host, port, family, socket.SOCK_STREAM):
  File "C:\Users\user\AppData\Local\Programs\Python\Python310\lib\socket.py", line 955, in getaddrinfo
    for res in _socket.getaddrinfo(host, port, family, type, proto, flags):
socket.gaierror: [Errno 11001] getaddrinfo failed

The above exception was the direct cause of the following exception:

Traceback (most recent call last):
  File "C:\Users\user\AppData\Local\Programs\Python\Python310\lib\site-packages\urllib3\connectionpool.py", line 787, in urlopen
    response = self._make_request(
  File "C:\Users\user\AppData\Local\Programs\Python\Python310\lib\site-packages\urllib3\connectionpool.py", line 488, in _make_request
    raise new_e
  File "C:\Users\user\AppData\Local\Programs\Python\Python310\lib\site-packages\urllib3\connectionpool.py", line 464, in _make_request
    self._validate_conn(conn)
  File "C:\Users\user\AppData\Local\Programs\Python\Python310\lib\site-packages\urllib3\connectionpool.py", line 1093, in _validate_conn
    conn.connect()
  File "C:\Users\user\AppData\Local\Programs\Python\Python310\lib\site-packages\urllib3\connection.py", line 704, in connect
    self.sock = sock = self._new_conn()
  File "C:\Users\user\AppData\Local\Programs\Python\Python310\lib\site-packages\urllib3\connection.py", line 205, in _new_conn
    raise NameResolutionError(self.host, self, e) from e
urllib3.exceptions.NameResolutionError: <urllib3.connection.HTTPSConnection object at 0x000001C430AEFC70>: Failed to resolve 'fapi.binance.com' ([Errno 11001] getaddrinfo failed)

The above exception was the direct cause of the following exception:

Traceback (most recent call last):
  File "C:\Users\user\AppData\Local\Programs\Python\Python310\lib\site-packages\requests\adapters.py", line 667, in send
    resp = conn.urlopen(
  File "C:\Users\user\AppData\Local\Programs\Python\Python310\lib\site-packages\urllib3\connectionpool.py", line 841, in urlopen
    retries = retries.increment(
  File "C:\Users\user\AppData\Local\Programs\Python\Python310\lib\site-packages\urllib3\util\retry.py", line 519, in increment
    raise MaxRetryError(_pool, url, reason) from reason  # type: ignore[arg-type]
urllib3.exceptions.MaxRetryError: HTTPSConnectionPool(host='fapi.binance.com', port=443): Max retries exceeded with url: /fapi/v3/positionRisk?recvWindow=10000&symbol=ALGOUSDT&timestamp=1752354105277&signature=2711194547784505f820d299617d96682c439e58739ad96f4f7e948f7ee507e1 (Caused by NameResolutionError("<urllib3.connection.HTTPSConnection object at 0x000001C430AEFC70>: Failed to resolve 'fapi.binance.com' ([Errno 11001] getaddrinfo failed)"))

During handling of the above exception, another exception occurred:

Traceback (most recent call last):
  File "D:\admin\MES PROJETS\Bot de trading\core\trade_executor.py", line 334, in cancel_all_open_orders_if_no_position
    positions = client.futures_position_information(symbol=symbol)
  File "C:\Users\user\AppData\Local\Programs\Python\Python310\lib\site-packages\binance\client.py", line 7835, in futures_position_information
    return self._request_futures_api("get", "positionRisk", True, 3, data=params)
  File "C:\Users\user\AppData\Local\Programs\Python\Python310\lib\site-packages\binance\client.py", line 126, in _request_futures_api
    return self._request(method, uri, signed, force_params, **kwargs)
  File "C:\Users\user\AppData\Local\Programs\Python\Python310\lib\site-packages\binance\client.py", line 88, in _request
    self.response = getattr(self.session, method)(uri, headers=headers, data=data, **kwargs)
  File "C:\Users\user\AppData\Local\Programs\Python\Python310\lib\site-packages\requests\sessions.py", line 602, in get
    return self.request("GET", url, **kwargs)
  File "C:\Users\user\AppData\Local\Programs\Python\Python310\lib\site-packages\requests\sessions.py", line 589, in request
    resp = self.send(prep, **send_kwargs)
  File "C:\Users\user\AppData\Local\Programs\Python\Python310\lib\site-packages\requests\sessions.py", line 703, in send
    r = adapter.send(request, **kwargs)
  File "C:\Users\user\AppData\Local\Programs\Python\Python310\lib\site-packages\requests\adapters.py", line 700, in send
    raise ConnectionError(e, request=request)
requests.exceptions.ConnectionError: HTTPSConnectionPool(host='fapi.binance.com', port=443): Max retries exceeded with url: /fapi/v3/positionRisk?recvWindow=10000&symbol=ALGOUSDT&timestamp=1752354105277&signature=2711194547784505f820d299617d96682c439e58739ad96f4f7e948f7ee507e1 (Caused by NameResolutionError("<urllib3.connection.HTTPSConnection object at 0x000001C430AEFC70>: Failed to resolve 'fapi.binance.com' ([Errno 11001] getaddrinfo failed)"))

Sat Jul 12 23:01:55 2025 - Erreur : Traceback (most recent call last):
  File "C:\Users\user\AppData\Local\Programs\Python\Python310\lib\site-packages\urllib3\connection.py", line 198, in _new_conn
    sock = connection.create_connection(
  File "C:\Users\user\AppData\Local\Programs\Python\Python310\lib\site-packages\urllib3\util\connection.py", line 60, in create_connection
    for res in socket.getaddrinfo(host, port, family, socket.SOCK_STREAM):
  File "C:\Users\user\AppData\Local\Programs\Python\Python310\lib\socket.py", line 955, in getaddrinfo
    for res in _socket.getaddrinfo(host, port, family, type, proto, flags):
socket.gaierror: [Errno 11001] getaddrinfo failed

The above exception was the direct cause of the following exception:

Traceback (most recent call last):
  File "C:\Users\user\AppData\Local\Programs\Python\Python310\lib\site-packages\urllib3\connectionpool.py", line 787, in urlopen
    response = self._make_request(
  File "C:\Users\user\AppData\Local\Programs\Python\Python310\lib\site-packages\urllib3\connectionpool.py", line 488, in _make_request
    raise new_e
  File "C:\Users\user\AppData\Local\Programs\Python\Python310\lib\site-packages\urllib3\connectionpool.py", line 464, in _make_request
    self._validate_conn(conn)
  File "C:\Users\user\AppData\Local\Programs\Python\Python310\lib\site-packages\urllib3\connectionpool.py", line 1093, in _validate_conn
    conn.connect()
  File "C:\Users\user\AppData\Local\Programs\Python\Python310\lib\site-packages\urllib3\connection.py", line 704, in connect
    self.sock = sock = self._new_conn()
  File "C:\Users\user\AppData\Local\Programs\Python\Python310\lib\site-packages\urllib3\connection.py", line 205, in _new_conn
    raise NameResolutionError(self.host, self, e) from e
urllib3.exceptions.NameResolutionError: <urllib3.connection.HTTPSConnection object at 0x000001C43077E8F0>: Failed to resolve 'fapi.binance.com' ([Errno 11001] getaddrinfo failed)

The above exception was the direct cause of the following exception:

Traceback (most recent call last):
  File "C:\Users\user\AppData\Local\Programs\Python\Python310\lib\site-packages\requests\adapters.py", line 667, in send
    resp = conn.urlopen(
  File "C:\Users\user\AppData\Local\Programs\Python\Python310\lib\site-packages\urllib3\connectionpool.py", line 841, in urlopen
    retries = retries.increment(
  File "C:\Users\user\AppData\Local\Programs\Python\Python310\lib\site-packages\urllib3\util\retry.py", line 519, in increment
    raise MaxRetryError(_pool, url, reason) from reason  # type: ignore[arg-type]
urllib3.exceptions.MaxRetryError: HTTPSConnectionPool(host='fapi.binance.com', port=443): Max retries exceeded with url: /fapi/v3/positionRisk?recvWindow=10000&symbol=ALGOUSDT&timestamp=1752354115291&signature=43c2cf28d4fca4489294a24ea3859e0ce9bbb3cadce2a2ffdbb1d95f02ee8466 (Caused by NameResolutionError("<urllib3.connection.HTTPSConnection object at 0x000001C43077E8F0>: Failed to resolve 'fapi.binance.com' ([Errno 11001] getaddrinfo failed)"))

During handling of the above exception, another exception occurred:

Traceback (most recent call last):
  File "D:\admin\MES PROJETS\Bot de trading\core\trade_executor.py", line 334, in cancel_all_open_orders_if_no_position
    positions = client.futures_position_information(symbol=symbol)
  File "C:\Users\user\AppData\Local\Programs\Python\Python310\lib\site-packages\binance\client.py", line 7835, in futures_position_information
    return self._request_futures_api("get", "positionRisk", True, 3, data=params)
  File "C:\Users\user\AppData\Local\Programs\Python\Python310\lib\site-packages\binance\client.py", line 126, in _request_futures_api
    return self._request(method, uri, signed, force_params, **kwargs)
  File "C:\Users\user\AppData\Local\Programs\Python\Python310\lib\site-packages\binance\client.py", line 88, in _request
    self.response = getattr(self.session, method)(uri, headers=headers, data=data, **kwargs)
  File "C:\Users\user\AppData\Local\Programs\Python\Python310\lib\site-packages\requests\sessions.py", line 602, in get
    return self.request("GET", url, **kwargs)
  File "C:\Users\user\AppData\Local\Programs\Python\Python310\lib\site-packages\requests\sessions.py", line 589, in request
    resp = self.send(prep, **send_kwargs)
  File "C:\Users\user\AppData\Local\Programs\Python\Python310\lib\site-packages\requests\sessions.py", line 703, in send
    r = adapter.send(request, **kwargs)
  File "C:\Users\user\AppData\Local\Programs\Python\Python310\lib\site-packages\requests\adapters.py", line 700, in send
    raise ConnectionError(e, request=request)
requests.exceptions.ConnectionError: HTTPSConnectionPool(host='fapi.binance.com', port=443): Max retries exceeded with url: /fapi/v3/positionRisk?recvWindow=10000&symbol=ALGOUSDT&timestamp=1752354115291&signature=43c2cf28d4fca4489294a24ea3859e0ce9bbb3cadce2a2ffdbb1d95f02ee8466 (Caused by NameResolutionError("<urllib3.connection.HTTPSConnection object at 0x000001C43077E8F0>: Failed to resolve 'fapi.binance.com' ([Errno 11001] getaddrinfo failed)"))

Sat Jul 12 23:02:05 2025 - Erreur : Traceback (most recent call last):
  File "C:\Users\user\AppData\Local\Programs\Python\Python310\lib\site-packages\urllib3\connection.py", line 198, in _new_conn
    sock = connection.create_connection(
  File "C:\Users\user\AppData\Local\Programs\Python\Python310\lib\site-packages\urllib3\util\connection.py", line 60, in create_connection
    for res in socket.getaddrinfo(host, port, family, socket.SOCK_STREAM):
  File "C:\Users\user\AppData\Local\Programs\Python\Python310\lib\socket.py", line 955, in getaddrinfo
    for res in _socket.getaddrinfo(host, port, family, type, proto, flags):
socket.gaierror: [Errno 11001] getaddrinfo failed

The above exception was the direct cause of the following exception:

Traceback (most recent call last):
  File "C:\Users\user\AppData\Local\Programs\Python\Python310\lib\site-packages\urllib3\connectionpool.py", line 787, in urlopen
    response = self._make_request(
  File "C:\Users\user\AppData\Local\Programs\Python\Python310\lib\site-packages\urllib3\connectionpool.py", line 488, in _make_request
    raise new_e
  File "C:\Users\user\AppData\Local\Programs\Python\Python310\lib\site-packages\urllib3\connectionpool.py", line 464, in _make_request
    self._validate_conn(conn)
  File "C:\Users\user\AppData\Local\Programs\Python\Python310\lib\site-packages\urllib3\connectionpool.py", line 1093, in _validate_conn
    conn.connect()
  File "C:\Users\user\AppData\Local\Programs\Python\Python310\lib\site-packages\urllib3\connection.py", line 704, in connect
    self.sock = sock = self._new_conn()
  File "C:\Users\user\AppData\Local\Programs\Python\Python310\lib\site-packages\urllib3\connection.py", line 205, in _new_conn
    raise NameResolutionError(self.host, self, e) from e
urllib3.exceptions.NameResolutionError: <urllib3.connection.HTTPSConnection object at 0x000001C430ABF490>: Failed to resolve 'fapi.binance.com' ([Errno 11001] getaddrinfo failed)

The above exception was the direct cause of the following exception:

Traceback (most recent call last):
  File "C:\Users\user\AppData\Local\Programs\Python\Python310\lib\site-packages\requests\adapters.py", line 667, in send
    resp = conn.urlopen(
  File "C:\Users\user\AppData\Local\Programs\Python\Python310\lib\site-packages\urllib3\connectionpool.py", line 841, in urlopen
    retries = retries.increment(
  File "C:\Users\user\AppData\Local\Programs\Python\Python310\lib\site-packages\urllib3\util\retry.py", line 519, in increment
    raise MaxRetryError(_pool, url, reason) from reason  # type: ignore[arg-type]
urllib3.exceptions.MaxRetryError: HTTPSConnectionPool(host='fapi.binance.com', port=443): Max retries exceeded with url: /fapi/v3/positionRisk?recvWindow=10000&symbol=ALGOUSDT&timestamp=1752354125306&signature=7491c9e40db2e98c697788381734af091bf47da8f257b82aef7513467dfe55dc (Caused by NameResolutionError("<urllib3.connection.HTTPSConnection object at 0x000001C430ABF490>: Failed to resolve 'fapi.binance.com' ([Errno 11001] getaddrinfo failed)"))

During handling of the above exception, another exception occurred:

Traceback (most recent call last):
  File "D:\admin\MES PROJETS\Bot de trading\core\trade_executor.py", line 334, in cancel_all_open_orders_if_no_position
    positions = client.futures_position_information(symbol=symbol)
  File "C:\Users\user\AppData\Local\Programs\Python\Python310\lib\site-packages\binance\client.py", line 7835, in futures_position_information
    return self._request_futures_api("get", "positionRisk", True, 3, data=params)
  File "C:\Users\user\AppData\Local\Programs\Python\Python310\lib\site-packages\binance\client.py", line 126, in _request_futures_api
    return self._request(method, uri, signed, force_params, **kwargs)
  File "C:\Users\user\AppData\Local\Programs\Python\Python310\lib\site-packages\binance\client.py", line 88, in _request
    self.response = getattr(self.session, method)(uri, headers=headers, data=data, **kwargs)
  File "C:\Users\user\AppData\Local\Programs\Python\Python310\lib\site-packages\requests\sessions.py", line 602, in get
    return self.request("GET", url, **kwargs)
  File "C:\Users\user\AppData\Local\Programs\Python\Python310\lib\site-packages\requests\sessions.py", line 589, in request
    resp = self.send(prep, **send_kwargs)
  File "C:\Users\user\AppData\Local\Programs\Python\Python310\lib\site-packages\requests\sessions.py", line 703, in send
    r = adapter.send(request, **kwargs)
  File "C:\Users\user\AppData\Local\Programs\Python\Python310\lib\site-packages\requests\adapters.py", line 700, in send
    raise ConnectionError(e, request=request)
requests.exceptions.ConnectionError: HTTPSConnectionPool(host='fapi.binance.com', port=443): Max retries exceeded with url: /fapi/v3/positionRisk?recvWindow=10000&symbol=ALGOUSDT&timestamp=1752354125306&signature=7491c9e40db2e98c697788381734af091bf47da8f257b82aef7513467dfe55dc (Caused by NameResolutionError("<urllib3.connection.HTTPSConnection object at 0x000001C430ABF490>: Failed to resolve 'fapi.binance.com' ([Errno 11001] getaddrinfo failed)"))

Sat Jul 12 23:02:15 2025 - Erreur : Traceback (most recent call last):
  File "C:\Users\user\AppData\Local\Programs\Python\Python310\lib\site-packages\urllib3\connection.py", line 198, in _new_conn
    sock = connection.create_connection(
  File "C:\Users\user\AppData\Local\Programs\Python\Python310\lib\site-packages\urllib3\util\connection.py", line 60, in create_connection
    for res in socket.getaddrinfo(host, port, family, socket.SOCK_STREAM):
  File "C:\Users\user\AppData\Local\Programs\Python\Python310\lib\socket.py", line 955, in getaddrinfo
    for res in _socket.getaddrinfo(host, port, family, type, proto, flags):
socket.gaierror: [Errno 11001] getaddrinfo failed

The above exception was the direct cause of the following exception:

Traceback (most recent call last):
  File "C:\Users\user\AppData\Local\Programs\Python\Python310\lib\site-packages\urllib3\connectionpool.py", line 787, in urlopen
    response = self._make_request(
  File "C:\Users\user\AppData\Local\Programs\Python\Python310\lib\site-packages\urllib3\connectionpool.py", line 488, in _make_request
    raise new_e
  File "C:\Users\user\AppData\Local\Programs\Python\Python310\lib\site-packages\urllib3\connectionpool.py", line 464, in _make_request
    self._validate_conn(conn)
  File "C:\Users\user\AppData\Local\Programs\Python\Python310\lib\site-packages\urllib3\connectionpool.py", line 1093, in _validate_conn
    conn.connect()
  File "C:\Users\user\AppData\Local\Programs\Python\Python310\lib\site-packages\urllib3\connection.py", line 704, in connect
    self.sock = sock = self._new_conn()
  File "C:\Users\user\AppData\Local\Programs\Python\Python310\lib\site-packages\urllib3\connection.py", line 205, in _new_conn
    raise NameResolutionError(self.host, self, e) from e
urllib3.exceptions.NameResolutionError: <urllib3.connection.HTTPSConnection object at 0x000001C430B4D810>: Failed to resolve 'fapi.binance.com' ([Errno 11001] getaddrinfo failed)

The above exception was the direct cause of the following exception:

Traceback (most recent call last):
  File "C:\Users\user\AppData\Local\Programs\Python\Python310\lib\site-packages\requests\adapters.py", line 667, in send
    resp = conn.urlopen(
  File "C:\Users\user\AppData\Local\Programs\Python\Python310\lib\site-packages\urllib3\connectionpool.py", line 841, in urlopen
    retries = retries.increment(
  File "C:\Users\user\AppData\Local\Programs\Python\Python310\lib\site-packages\urllib3\util\retry.py", line 519, in increment
    raise MaxRetryError(_pool, url, reason) from reason  # type: ignore[arg-type]
urllib3.exceptions.MaxRetryError: HTTPSConnectionPool(host='fapi.binance.com', port=443): Max retries exceeded with url: /fapi/v3/positionRisk?recvWindow=10000&symbol=ALGOUSDT&timestamp=1752354135320&signature=057f91edf92c1388bda4d1a4ebbcd9ac72e8f669f05bfc97b481c0ce82b5df7d (Caused by NameResolutionError("<urllib3.connection.HTTPSConnection object at 0x000001C430B4D810>: Failed to resolve 'fapi.binance.com' ([Errno 11001] getaddrinfo failed)"))

During handling of the above exception, another exception occurred:

Traceback (most recent call last):
  File "D:\admin\MES PROJETS\Bot de trading\core\trade_executor.py", line 334, in cancel_all_open_orders_if_no_position
    positions = client.futures_position_information(symbol=symbol)
  File "C:\Users\user\AppData\Local\Programs\Python\Python310\lib\site-packages\binance\client.py", line 7835, in futures_position_information
    return self._request_futures_api("get", "positionRisk", True, 3, data=params)
  File "C:\Users\user\AppData\Local\Programs\Python\Python310\lib\site-packages\binance\client.py", line 126, in _request_futures_api
    return self._request(method, uri, signed, force_params, **kwargs)
  File "C:\Users\user\AppData\Local\Programs\Python\Python310\lib\site-packages\binance\client.py", line 88, in _request
    self.response = getattr(self.session, method)(uri, headers=headers, data=data, **kwargs)
  File "C:\Users\user\AppData\Local\Programs\Python\Python310\lib\site-packages\requests\sessions.py", line 602, in get
    return self.request("GET", url, **kwargs)
  File "C:\Users\user\AppData\Local\Programs\Python\Python310\lib\site-packages\requests\sessions.py", line 589, in request
    resp = self.send(prep, **send_kwargs)
  File "C:\Users\user\AppData\Local\Programs\Python\Python310\lib\site-packages\requests\sessions.py", line 703, in send
    r = adapter.send(request, **kwargs)
  File "C:\Users\user\AppData\Local\Programs\Python\Python310\lib\site-packages\requests\adapters.py", line 700, in send
    raise ConnectionError(e, request=request)
requests.exceptions.ConnectionError: HTTPSConnectionPool(host='fapi.binance.com', port=443): Max retries exceeded with url: /fapi/v3/positionRisk?recvWindow=10000&symbol=ALGOUSDT&timestamp=1752354135320&signature=057f91edf92c1388bda4d1a4ebbcd9ac72e8f669f05bfc97b481c0ce82b5df7d (Caused by NameResolutionError("<urllib3.connection.HTTPSConnection object at 0x000001C430B4D810>: Failed to resolve 'fapi.binance.com' ([Errno 11001] getaddrinfo failed)"))

Sat Jul 12 23:02:25 2025 - Erreur : Traceback (most recent call last):
  File "C:\Users\user\AppData\Local\Programs\Python\Python310\lib\site-packages\urllib3\connection.py", line 198, in _new_conn
    sock = connection.create_connection(
  File "C:\Users\user\AppData\Local\Programs\Python\Python310\lib\site-packages\urllib3\util\connection.py", line 60, in create_connection
    for res in socket.getaddrinfo(host, port, family, socket.SOCK_STREAM):
  File "C:\Users\user\AppData\Local\Programs\Python\Python310\lib\socket.py", line 955, in getaddrinfo
    for res in _socket.getaddrinfo(host, port, family, type, proto, flags):
socket.gaierror: [Errno 11001] getaddrinfo failed

The above exception was the direct cause of the following exception:

Traceback (most recent call last):
  File "C:\Users\user\AppData\Local\Programs\Python\Python310\lib\site-packages\urllib3\connectionpool.py", line 787, in urlopen
    response = self._make_request(
  File "C:\Users\user\AppData\Local\Programs\Python\Python310\lib\site-packages\urllib3\connectionpool.py", line 488, in _make_request
    raise new_e
  File "C:\Users\user\AppData\Local\Programs\Python\Python310\lib\site-packages\urllib3\connectionpool.py", line 464, in _make_request
    self._validate_conn(conn)
  File "C:\Users\user\AppData\Local\Programs\Python\Python310\lib\site-packages\urllib3\connectionpool.py", line 1093, in _validate_conn
    conn.connect()
  File "C:\Users\user\AppData\Local\Programs\Python\Python310\lib\site-packages\urllib3\connection.py", line 704, in connect
    self.sock = sock = self._new_conn()
  File "C:\Users\user\AppData\Local\Programs\Python\Python310\lib\site-packages\urllib3\connection.py", line 205, in _new_conn
    raise NameResolutionError(self.host, self, e) from e
urllib3.exceptions.NameResolutionError: <urllib3.connection.HTTPSConnection object at 0x000001C430ABC6A0>: Failed to resolve 'fapi.binance.com' ([Errno 11001] getaddrinfo failed)

The above exception was the direct cause of the following exception:

Traceback (most recent call last):
  File "C:\Users\user\AppData\Local\Programs\Python\Python310\lib\site-packages\requests\adapters.py", line 667, in send
    resp = conn.urlopen(
  File "C:\Users\user\AppData\Local\Programs\Python\Python310\lib\site-packages\urllib3\connectionpool.py", line 841, in urlopen
    retries = retries.increment(
  File "C:\Users\user\AppData\Local\Programs\Python\Python310\lib\site-packages\urllib3\util\retry.py", line 519, in increment
    raise MaxRetryError(_pool, url, reason) from reason  # type: ignore[arg-type]
urllib3.exceptions.MaxRetryError: HTTPSConnectionPool(host='fapi.binance.com', port=443): Max retries exceeded with url: /fapi/v3/positionRisk?recvWindow=10000&symbol=ALGOUSDT&timestamp=1752354145340&signature=5c1b6ca83b3ef55e84614b319a8a73f77d9cbac34466ac24ce98739d245c73a9 (Caused by NameResolutionError("<urllib3.connection.HTTPSConnection object at 0x000001C430ABC6A0>: Failed to resolve 'fapi.binance.com' ([Errno 11001] getaddrinfo failed)"))

During handling of the above exception, another exception occurred:

Traceback (most recent call last):
  File "D:\admin\MES PROJETS\Bot de trading\core\trade_executor.py", line 334, in cancel_all_open_orders_if_no_position
    positions = client.futures_position_information(symbol=symbol)
  File "C:\Users\user\AppData\Local\Programs\Python\Python310\lib\site-packages\binance\client.py", line 7835, in futures_position_information
    return self._request_futures_api("get", "positionRisk", True, 3, data=params)
  File "C:\Users\user\AppData\Local\Programs\Python\Python310\lib\site-packages\binance\client.py", line 126, in _request_futures_api
    return self._request(method, uri, signed, force_params, **kwargs)
  File "C:\Users\user\AppData\Local\Programs\Python\Python310\lib\site-packages\binance\client.py", line 88, in _request
    self.response = getattr(self.session, method)(uri, headers=headers, data=data, **kwargs)
  File "C:\Users\user\AppData\Local\Programs\Python\Python310\lib\site-packages\requests\sessions.py", line 602, in get
    return self.request("GET", url, **kwargs)
  File "C:\Users\user\AppData\Local\Programs\Python\Python310\lib\site-packages\requests\sessions.py", line 589, in request
    resp = self.send(prep, **send_kwargs)
  File "C:\Users\user\AppData\Local\Programs\Python\Python310\lib\site-packages\requests\sessions.py", line 703, in send
    r = adapter.send(request, **kwargs)
  File "C:\Users\user\AppData\Local\Programs\Python\Python310\lib\site-packages\requests\adapters.py", line 700, in send
    raise ConnectionError(e, request=request)
requests.exceptions.ConnectionError: HTTPSConnectionPool(host='fapi.binance.com', port=443): Max retries exceeded with url: /fapi/v3/positionRisk?recvWindow=10000&symbol=ALGOUSDT&timestamp=1752354145340&signature=5c1b6ca83b3ef55e84614b319a8a73f77d9cbac34466ac24ce98739d245c73a9 (Caused by NameResolutionError("<urllib3.connection.HTTPSConnection object at 0x000001C430ABC6A0>: Failed to resolve 'fapi.binance.com' ([Errno 11001] getaddrinfo failed)"))

Sat Jul 12 23:02:35 2025 - Erreur : Traceback (most recent call last):
  File "C:\Users\user\AppData\Local\Programs\Python\Python310\lib\site-packages\urllib3\connection.py", line 198, in _new_conn
    sock = connection.create_connection(
  File "C:\Users\user\AppData\Local\Programs\Python\Python310\lib\site-packages\urllib3\util\connection.py", line 60, in create_connection
    for res in socket.getaddrinfo(host, port, family, socket.SOCK_STREAM):
  File "C:\Users\user\AppData\Local\Programs\Python\Python310\lib\socket.py", line 955, in getaddrinfo
    for res in _socket.getaddrinfo(host, port, family, type, proto, flags):
socket.gaierror: [Errno 11001] getaddrinfo failed

The above exception was the direct cause of the following exception:

Traceback (most recent call last):
  File "C:\Users\user\AppData\Local\Programs\Python\Python310\lib\site-packages\urllib3\connectionpool.py", line 787, in urlopen
    response = self._make_request(
  File "C:\Users\user\AppData\Local\Programs\Python\Python310\lib\site-packages\urllib3\connectionpool.py", line 488, in _make_request
    raise new_e
  File "C:\Users\user\AppData\Local\Programs\Python\Python310\lib\site-packages\urllib3\connectionpool.py", line 464, in _make_request
    self._validate_conn(conn)
  File "C:\Users\user\AppData\Local\Programs\Python\Python310\lib\site-packages\urllib3\connectionpool.py", line 1093, in _validate_conn
    conn.connect()
  File "C:\Users\user\AppData\Local\Programs\Python\Python310\lib\site-packages\urllib3\connection.py", line 704, in connect
    self.sock = sock = self._new_conn()
  File "C:\Users\user\AppData\Local\Programs\Python\Python310\lib\site-packages\urllib3\connection.py", line 205, in _new_conn
    raise NameResolutionError(self.host, self, e) from e
urllib3.exceptions.NameResolutionError: <urllib3.connection.HTTPSConnection object at 0x000001C43077F1C0>: Failed to resolve 'fapi.binance.com' ([Errno 11001] getaddrinfo failed)

The above exception was the direct cause of the following exception:

Traceback (most recent call last):
  File "C:\Users\user\AppData\Local\Programs\Python\Python310\lib\site-packages\requests\adapters.py", line 667, in send
    resp = conn.urlopen(
  File "C:\Users\user\AppData\Local\Programs\Python\Python310\lib\site-packages\urllib3\connectionpool.py", line 841, in urlopen
    retries = retries.increment(
  File "C:\Users\user\AppData\Local\Programs\Python\Python310\lib\site-packages\urllib3\util\retry.py", line 519, in increment
    raise MaxRetryError(_pool, url, reason) from reason  # type: ignore[arg-type]
urllib3.exceptions.MaxRetryError: HTTPSConnectionPool(host='fapi.binance.com', port=443): Max retries exceeded with url: /fapi/v3/positionRisk?recvWindow=10000&symbol=ALGOUSDT&timestamp=1752354155350&signature=912edff91f3c9331ce6e804ccf0be96677fa4a0cdcf0004e30bebdc07b19aa2f (Caused by NameResolutionError("<urllib3.connection.HTTPSConnection object at 0x000001C43077F1C0>: Failed to resolve 'fapi.binance.com' ([Errno 11001] getaddrinfo failed)"))

During handling of the above exception, another exception occurred:

Traceback (most recent call last):
  File "D:\admin\MES PROJETS\Bot de trading\core\trade_executor.py", line 334, in cancel_all_open_orders_if_no_position
    positions = client.futures_position_information(symbol=symbol)
  File "C:\Users\user\AppData\Local\Programs\Python\Python310\lib\site-packages\binance\client.py", line 7835, in futures_position_information
    return self._request_futures_api("get", "positionRisk", True, 3, data=params)
  File "C:\Users\user\AppData\Local\Programs\Python\Python310\lib\site-packages\binance\client.py", line 126, in _request_futures_api
    return self._request(method, uri, signed, force_params, **kwargs)
  File "C:\Users\user\AppData\Local\Programs\Python\Python310\lib\site-packages\binance\client.py", line 88, in _request
    self.response = getattr(self.session, method)(uri, headers=headers, data=data, **kwargs)
  File "C:\Users\user\AppData\Local\Programs\Python\Python310\lib\site-packages\requests\sessions.py", line 602, in get
    return self.request("GET", url, **kwargs)
  File "C:\Users\user\AppData\Local\Programs\Python\Python310\lib\site-packages\requests\sessions.py", line 589, in request
    resp = self.send(prep, **send_kwargs)
  File "C:\Users\user\AppData\Local\Programs\Python\Python310\lib\site-packages\requests\sessions.py", line 703, in send
    r = adapter.send(request, **kwargs)
  File "C:\Users\user\AppData\Local\Programs\Python\Python310\lib\site-packages\requests\adapters.py", line 700, in send
    raise ConnectionError(e, request=request)
requests.exceptions.ConnectionError: HTTPSConnectionPool(host='fapi.binance.com', port=443): Max retries exceeded with url: /fapi/v3/positionRisk?recvWindow=10000&symbol=ALGOUSDT&timestamp=1752354155350&signature=912edff91f3c9331ce6e804ccf0be96677fa4a0cdcf0004e30bebdc07b19aa2f (Caused by NameResolutionError("<urllib3.connection.HTTPSConnection object at 0x000001C43077F1C0>: Failed to resolve 'fapi.binance.com' ([Errno 11001] getaddrinfo failed)"))

Sat Jul 12 23:02:45 2025 - Erreur : Traceback (most recent call last):
  File "C:\Users\user\AppData\Local\Programs\Python\Python310\lib\site-packages\urllib3\connection.py", line 198, in _new_conn
    sock = connection.create_connection(
  File "C:\Users\user\AppData\Local\Programs\Python\Python310\lib\site-packages\urllib3\util\connection.py", line 60, in create_connection
    for res in socket.getaddrinfo(host, port, family, socket.SOCK_STREAM):
  File "C:\Users\user\AppData\Local\Programs\Python\Python310\lib\socket.py", line 955, in getaddrinfo
    for res in _socket.getaddrinfo(host, port, family, type, proto, flags):
socket.gaierror: [Errno 11001] getaddrinfo failed

The above exception was the direct cause of the following exception:

Traceback (most recent call last):
  File "C:\Users\user\AppData\Local\Programs\Python\Python310\lib\site-packages\urllib3\connectionpool.py", line 787, in urlopen
    response = self._make_request(
  File "C:\Users\user\AppData\Local\Programs\Python\Python310\lib\site-packages\urllib3\connectionpool.py", line 488, in _make_request
    raise new_e
  File "C:\Users\user\AppData\Local\Programs\Python\Python310\lib\site-packages\urllib3\connectionpool.py", line 464, in _make_request
    self._validate_conn(conn)
  File "C:\Users\user\AppData\Local\Programs\Python\Python310\lib\site-packages\urllib3\connectionpool.py", line 1093, in _validate_conn
    conn.connect()
  File "C:\Users\user\AppData\Local\Programs\Python\Python310\lib\site-packages\urllib3\connection.py", line 704, in connect
    self.sock = sock = self._new_conn()
  File "C:\Users\user\AppData\Local\Programs\Python\Python310\lib\site-packages\urllib3\connection.py", line 205, in _new_conn
    raise NameResolutionError(self.host, self, e) from e
urllib3.exceptions.NameResolutionError: <urllib3.connection.HTTPSConnection object at 0x000001C430AEE0E0>: Failed to resolve 'fapi.binance.com' ([Errno 11001] getaddrinfo failed)

The above exception was the direct cause of the following exception:

Traceback (most recent call last):
  File "C:\Users\user\AppData\Local\Programs\Python\Python310\lib\site-packages\requests\adapters.py", line 667, in send
    resp = conn.urlopen(
  File "C:\Users\user\AppData\Local\Programs\Python\Python310\lib\site-packages\urllib3\connectionpool.py", line 841, in urlopen
    retries = retries.increment(
  File "C:\Users\user\AppData\Local\Programs\Python\Python310\lib\site-packages\urllib3\util\retry.py", line 519, in increment
    raise MaxRetryError(_pool, url, reason) from reason  # type: ignore[arg-type]
urllib3.exceptions.MaxRetryError: HTTPSConnectionPool(host='fapi.binance.com', port=443): Max retries exceeded with url: /fapi/v3/positionRisk?recvWindow=10000&symbol=ALGOUSDT&timestamp=1752354165365&signature=58caf572f8af79b3f1e07982e92bb8105c25678352d983827482667413d09ad0 (Caused by NameResolutionError("<urllib3.connection.HTTPSConnection object at 0x000001C430AEE0E0>: Failed to resolve 'fapi.binance.com' ([Errno 11001] getaddrinfo failed)"))

During handling of the above exception, another exception occurred:

Traceback (most recent call last):
  File "D:\admin\MES PROJETS\Bot de trading\core\trade_executor.py", line 334, in cancel_all_open_orders_if_no_position
    positions = client.futures_position_information(symbol=symbol)
  File "C:\Users\user\AppData\Local\Programs\Python\Python310\lib\site-packages\binance\client.py", line 7835, in futures_position_information
    return self._request_futures_api("get", "positionRisk", True, 3, data=params)
  File "C:\Users\user\AppData\Local\Programs\Python\Python310\lib\site-packages\binance\client.py", line 126, in _request_futures_api
    return self._request(method, uri, signed, force_params, **kwargs)
  File "C:\Users\user\AppData\Local\Programs\Python\Python310\lib\site-packages\binance\client.py", line 88, in _request
    self.response = getattr(self.session, method)(uri, headers=headers, data=data, **kwargs)
  File "C:\Users\user\AppData\Local\Programs\Python\Python310\lib\site-packages\requests\sessions.py", line 602, in get
    return self.request("GET", url, **kwargs)
  File "C:\Users\user\AppData\Local\Programs\Python\Python310\lib\site-packages\requests\sessions.py", line 589, in request
    resp = self.send(prep, **send_kwargs)
  File "C:\Users\user\AppData\Local\Programs\Python\Python310\lib\site-packages\requests\sessions.py", line 703, in send
    r = adapter.send(request, **kwargs)
  File "C:\Users\user\AppData\Local\Programs\Python\Python310\lib\site-packages\requests\adapters.py", line 700, in send
    raise ConnectionError(e, request=request)
requests.exceptions.ConnectionError: HTTPSConnectionPool(host='fapi.binance.com', port=443): Max retries exceeded with url: /fapi/v3/positionRisk?recvWindow=10000&symbol=ALGOUSDT&timestamp=1752354165365&signature=58caf572f8af79b3f1e07982e92bb8105c25678352d983827482667413d09ad0 (Caused by NameResolutionError("<urllib3.connection.HTTPSConnection object at 0x000001C430AEE0E0>: Failed to resolve 'fapi.binance.com' ([Errno 11001] getaddrinfo failed)"))

Sat Jul 12 23:02:55 2025 - Erreur : Traceback (most recent call last):
  File "C:\Users\user\AppData\Local\Programs\Python\Python310\lib\site-packages\urllib3\connection.py", line 198, in _new_conn
    sock = connection.create_connection(
  File "C:\Users\user\AppData\Local\Programs\Python\Python310\lib\site-packages\urllib3\util\connection.py", line 60, in create_connection
    for res in socket.getaddrinfo(host, port, family, socket.SOCK_STREAM):
  File "C:\Users\user\AppData\Local\Programs\Python\Python310\lib\socket.py", line 955, in getaddrinfo
    for res in _socket.getaddrinfo(host, port, family, type, proto, flags):
socket.gaierror: [Errno 11001] getaddrinfo failed

The above exception was the direct cause of the following exception:

Traceback (most recent call last):
  File "C:\Users\user\AppData\Local\Programs\Python\Python310\lib\site-packages\urllib3\connectionpool.py", line 787, in urlopen
    response = self._make_request(
  File "C:\Users\user\AppData\Local\Programs\Python\Python310\lib\site-packages\urllib3\connectionpool.py", line 488, in _make_request
    raise new_e
  File "C:\Users\user\AppData\Local\Programs\Python\Python310\lib\site-packages\urllib3\connectionpool.py", line 464, in _make_request
    self._validate_conn(conn)
  File "C:\Users\user\AppData\Local\Programs\Python\Python310\lib\site-packages\urllib3\connectionpool.py", line 1093, in _validate_conn
    conn.connect()
  File "C:\Users\user\AppData\Local\Programs\Python\Python310\lib\site-packages\urllib3\connection.py", line 704, in connect
    self.sock = sock = self._new_conn()
  File "C:\Users\user\AppData\Local\Programs\Python\Python310\lib\site-packages\urllib3\connection.py", line 205, in _new_conn
    raise NameResolutionError(self.host, self, e) from e
urllib3.exceptions.NameResolutionError: <urllib3.connection.HTTPSConnection object at 0x000001C430AFCA60>: Failed to resolve 'fapi.binance.com' ([Errno 11001] getaddrinfo failed)

The above exception was the direct cause of the following exception:

Traceback (most recent call last):
  File "C:\Users\user\AppData\Local\Programs\Python\Python310\lib\site-packages\requests\adapters.py", line 667, in send
    resp = conn.urlopen(
  File "C:\Users\user\AppData\Local\Programs\Python\Python310\lib\site-packages\urllib3\connectionpool.py", line 841, in urlopen
    retries = retries.increment(
  File "C:\Users\user\AppData\Local\Programs\Python\Python310\lib\site-packages\urllib3\util\retry.py", line 519, in increment
    raise MaxRetryError(_pool, url, reason) from reason  # type: ignore[arg-type]
urllib3.exceptions.MaxRetryError: HTTPSConnectionPool(host='fapi.binance.com', port=443): Max retries exceeded with url: /fapi/v3/positionRisk?recvWindow=10000&symbol=ALGOUSDT&timestamp=1752354175382&signature=b624d2bf32749405dbe5e1f6a1c90ee1f14de893f04553d43e1f3acda9458c77 (Caused by NameResolutionError("<urllib3.connection.HTTPSConnection object at 0x000001C430AFCA60>: Failed to resolve 'fapi.binance.com' ([Errno 11001] getaddrinfo failed)"))

During handling of the above exception, another exception occurred:

Traceback (most recent call last):
  File "D:\admin\MES PROJETS\Bot de trading\core\trade_executor.py", line 334, in cancel_all_open_orders_if_no_position
    positions = client.futures_position_information(symbol=symbol)
  File "C:\Users\user\AppData\Local\Programs\Python\Python310\lib\site-packages\binance\client.py", line 7835, in futures_position_information
    return self._request_futures_api("get", "positionRisk", True, 3, data=params)
  File "C:\Users\user\AppData\Local\Programs\Python\Python310\lib\site-packages\binance\client.py", line 126, in _request_futures_api
    return self._request(method, uri, signed, force_params, **kwargs)
  File "C:\Users\user\AppData\Local\Programs\Python\Python310\lib\site-packages\binance\client.py", line 88, in _request
    self.response = getattr(self.session, method)(uri, headers=headers, data=data, **kwargs)
  File "C:\Users\user\AppData\Local\Programs\Python\Python310\lib\site-packages\requests\sessions.py", line 602, in get
    return self.request("GET", url, **kwargs)
  File "C:\Users\user\AppData\Local\Programs\Python\Python310\lib\site-packages\requests\sessions.py", line 589, in request
    resp = self.send(prep, **send_kwargs)
  File "C:\Users\user\AppData\Local\Programs\Python\Python310\lib\site-packages\requests\sessions.py", line 703, in send
    r = adapter.send(request, **kwargs)
  File "C:\Users\user\AppData\Local\Programs\Python\Python310\lib\site-packages\requests\adapters.py", line 700, in send
    raise ConnectionError(e, request=request)
requests.exceptions.ConnectionError: HTTPSConnectionPool(host='fapi.binance.com', port=443): Max retries exceeded with url: /fapi/v3/positionRisk?recvWindow=10000&symbol=ALGOUSDT&timestamp=1752354175382&signature=b624d2bf32749405dbe5e1f6a1c90ee1f14de893f04553d43e1f3acda9458c77 (Caused by NameResolutionError("<urllib3.connection.HTTPSConnection object at 0x000001C430AFCA60>: Failed to resolve 'fapi.binance.com' ([Errno 11001] getaddrinfo failed)"))

Sat Jul 12 23:03:05 2025 - Erreur : Traceback (most recent call last):
  File "C:\Users\user\AppData\Local\Programs\Python\Python310\lib\site-packages\urllib3\connection.py", line 198, in _new_conn
    sock = connection.create_connection(
  File "C:\Users\user\AppData\Local\Programs\Python\Python310\lib\site-packages\urllib3\util\connection.py", line 60, in create_connection
    for res in socket.getaddrinfo(host, port, family, socket.SOCK_STREAM):
  File "C:\Users\user\AppData\Local\Programs\Python\Python310\lib\socket.py", line 955, in getaddrinfo
    for res in _socket.getaddrinfo(host, port, family, type, proto, flags):
socket.gaierror: [Errno 11001] getaddrinfo failed

The above exception was the direct cause of the following exception:

Traceback (most recent call last):
  File "C:\Users\user\AppData\Local\Programs\Python\Python310\lib\site-packages\urllib3\connectionpool.py", line 787, in urlopen
    response = self._make_request(
  File "C:\Users\user\AppData\Local\Programs\Python\Python310\lib\site-packages\urllib3\connectionpool.py", line 488, in _make_request
    raise new_e
  File "C:\Users\user\AppData\Local\Programs\Python\Python310\lib\site-packages\urllib3\connectionpool.py", line 464, in _make_request
    self._validate_conn(conn)
  File "C:\Users\user\AppData\Local\Programs\Python\Python310\lib\site-packages\urllib3\connectionpool.py", line 1093, in _validate_conn
    conn.connect()
  File "C:\Users\user\AppData\Local\Programs\Python\Python310\lib\site-packages\urllib3\connection.py", line 704, in connect
    self.sock = sock = self._new_conn()
  File "C:\Users\user\AppData\Local\Programs\Python\Python310\lib\site-packages\urllib3\connection.py", line 205, in _new_conn
    raise NameResolutionError(self.host, self, e) from e
urllib3.exceptions.NameResolutionError: <urllib3.connection.HTTPSConnection object at 0x000001C430B2A260>: Failed to resolve 'fapi.binance.com' ([Errno 11001] getaddrinfo failed)

The above exception was the direct cause of the following exception:

Traceback (most recent call last):
  File "C:\Users\user\AppData\Local\Programs\Python\Python310\lib\site-packages\requests\adapters.py", line 667, in send
    resp = conn.urlopen(
  File "C:\Users\user\AppData\Local\Programs\Python\Python310\lib\site-packages\urllib3\connectionpool.py", line 841, in urlopen
    retries = retries.increment(
  File "C:\Users\user\AppData\Local\Programs\Python\Python310\lib\site-packages\urllib3\util\retry.py", line 519, in increment
    raise MaxRetryError(_pool, url, reason) from reason  # type: ignore[arg-type]
urllib3.exceptions.MaxRetryError: HTTPSConnectionPool(host='fapi.binance.com', port=443): Max retries exceeded with url: /fapi/v3/positionRisk?recvWindow=10000&symbol=ALGOUSDT&timestamp=1752354185389&signature=b7bef56ca8792e8205d11577cb1cdb85be08b94901656f5e31fcf57d20f8dab0 (Caused by NameResolutionError("<urllib3.connection.HTTPSConnection object at 0x000001C430B2A260>: Failed to resolve 'fapi.binance.com' ([Errno 11001] getaddrinfo failed)"))

During handling of the above exception, another exception occurred:

Traceback (most recent call last):
  File "D:\admin\MES PROJETS\Bot de trading\core\trade_executor.py", line 334, in cancel_all_open_orders_if_no_position
    positions = client.futures_position_information(symbol=symbol)
  File "C:\Users\user\AppData\Local\Programs\Python\Python310\lib\site-packages\binance\client.py", line 7835, in futures_position_information
    return self._request_futures_api("get", "positionRisk", True, 3, data=params)
  File "C:\Users\user\AppData\Local\Programs\Python\Python310\lib\site-packages\binance\client.py", line 126, in _request_futures_api
    return self._request(method, uri, signed, force_params, **kwargs)
  File "C:\Users\user\AppData\Local\Programs\Python\Python310\lib\site-packages\binance\client.py", line 88, in _request
    self.response = getattr(self.session, method)(uri, headers=headers, data=data, **kwargs)
  File "C:\Users\user\AppData\Local\Programs\Python\Python310\lib\site-packages\requests\sessions.py", line 602, in get
    return self.request("GET", url, **kwargs)
  File "C:\Users\user\AppData\Local\Programs\Python\Python310\lib\site-packages\requests\sessions.py", line 589, in request
    resp = self.send(prep, **send_kwargs)
  File "C:\Users\user\AppData\Local\Programs\Python\Python310\lib\site-packages\requests\sessions.py", line 703, in send
    r = adapter.send(request, **kwargs)
  File "C:\Users\user\AppData\Local\Programs\Python\Python310\lib\site-packages\requests\adapters.py", line 700, in send
    raise ConnectionError(e, request=request)
requests.exceptions.ConnectionError: HTTPSConnectionPool(host='fapi.binance.com', port=443): Max retries exceeded with url: /fapi/v3/positionRisk?recvWindow=10000&symbol=ALGOUSDT&timestamp=1752354185389&signature=b7bef56ca8792e8205d11577cb1cdb85be08b94901656f5e31fcf57d20f8dab0 (Caused by NameResolutionError("<urllib3.connection.HTTPSConnection object at 0x000001C430B2A260>: Failed to resolve 'fapi.binance.com' ([Errno 11001] getaddrinfo failed)"))

Sat Jul 12 23:03:15 2025 - Erreur : Traceback (most recent call last):
  File "C:\Users\user\AppData\Local\Programs\Python\Python310\lib\site-packages\urllib3\connection.py", line 198, in _new_conn
    sock = connection.create_connection(
  File "C:\Users\user\AppData\Local\Programs\Python\Python310\lib\site-packages\urllib3\util\connection.py", line 60, in create_connection
    for res in socket.getaddrinfo(host, port, family, socket.SOCK_STREAM):
  File "C:\Users\user\AppData\Local\Programs\Python\Python310\lib\socket.py", line 955, in getaddrinfo
    for res in _socket.getaddrinfo(host, port, family, type, proto, flags):
socket.gaierror: [Errno 11001] getaddrinfo failed

The above exception was the direct cause of the following exception:

Traceback (most recent call last):
  File "C:\Users\user\AppData\Local\Programs\Python\Python310\lib\site-packages\urllib3\connectionpool.py", line 787, in urlopen
    response = self._make_request(
  File "C:\Users\user\AppData\Local\Programs\Python\Python310\lib\site-packages\urllib3\connectionpool.py", line 488, in _make_request
    raise new_e
  File "C:\Users\user\AppData\Local\Programs\Python\Python310\lib\site-packages\urllib3\connectionpool.py", line 464, in _make_request
    self._validate_conn(conn)
  File "C:\Users\user\AppData\Local\Programs\Python\Python310\lib\site-packages\urllib3\connectionpool.py", line 1093, in _validate_conn
    conn.connect()
  File "C:\Users\user\AppData\Local\Programs\Python\Python310\lib\site-packages\urllib3\connection.py", line 704, in connect
    self.sock = sock = self._new_conn()
  File "C:\Users\user\AppData\Local\Programs\Python\Python310\lib\site-packages\urllib3\connection.py", line 205, in _new_conn
    raise NameResolutionError(self.host, self, e) from e
urllib3.exceptions.NameResolutionError: <urllib3.connection.HTTPSConnection object at 0x000001C430B28910>: Failed to resolve 'fapi.binance.com' ([Errno 11001] getaddrinfo failed)

The above exception was the direct cause of the following exception:

Traceback (most recent call last):
  File "C:\Users\user\AppData\Local\Programs\Python\Python310\lib\site-packages\requests\adapters.py", line 667, in send
    resp = conn.urlopen(
  File "C:\Users\user\AppData\Local\Programs\Python\Python310\lib\site-packages\urllib3\connectionpool.py", line 841, in urlopen
    retries = retries.increment(
  File "C:\Users\user\AppData\Local\Programs\Python\Python310\lib\site-packages\urllib3\util\retry.py", line 519, in increment
    raise MaxRetryError(_pool, url, reason) from reason  # type: ignore[arg-type]
urllib3.exceptions.MaxRetryError: HTTPSConnectionPool(host='fapi.binance.com', port=443): Max retries exceeded with url: /fapi/v3/positionRisk?recvWindow=10000&symbol=ALGOUSDT&timestamp=1752354195408&signature=67a7ada3511d770d162c360c1d65561f7921a3a8caf07595c86fbe09b7937fbe (Caused by NameResolutionError("<urllib3.connection.HTTPSConnection object at 0x000001C430B28910>: Failed to resolve 'fapi.binance.com' ([Errno 11001] getaddrinfo failed)"))

During handling of the above exception, another exception occurred:

Traceback (most recent call last):
  File "D:\admin\MES PROJETS\Bot de trading\core\trade_executor.py", line 334, in cancel_all_open_orders_if_no_position
    positions = client.futures_position_information(symbol=symbol)
  File "C:\Users\user\AppData\Local\Programs\Python\Python310\lib\site-packages\binance\client.py", line 7835, in futures_position_information
    return self._request_futures_api("get", "positionRisk", True, 3, data=params)
  File "C:\Users\user\AppData\Local\Programs\Python\Python310\lib\site-packages\binance\client.py", line 126, in _request_futures_api
    return self._request(method, uri, signed, force_params, **kwargs)
  File "C:\Users\user\AppData\Local\Programs\Python\Python310\lib\site-packages\binance\client.py", line 88, in _request
    self.response = getattr(self.session, method)(uri, headers=headers, data=data, **kwargs)
  File "C:\Users\user\AppData\Local\Programs\Python\Python310\lib\site-packages\requests\sessions.py", line 602, in get
    return self.request("GET", url, **kwargs)
  File "C:\Users\user\AppData\Local\Programs\Python\Python310\lib\site-packages\requests\sessions.py", line 589, in request
    resp = self.send(prep, **send_kwargs)
  File "C:\Users\user\AppData\Local\Programs\Python\Python310\lib\site-packages\requests\sessions.py", line 703, in send
    r = adapter.send(request, **kwargs)
  File "C:\Users\user\AppData\Local\Programs\Python\Python310\lib\site-packages\requests\adapters.py", line 700, in send
    raise ConnectionError(e, request=request)
requests.exceptions.ConnectionError: HTTPSConnectionPool(host='fapi.binance.com', port=443): Max retries exceeded with url: /fapi/v3/positionRisk?recvWindow=10000&symbol=ALGOUSDT&timestamp=1752354195408&signature=67a7ada3511d770d162c360c1d65561f7921a3a8caf07595c86fbe09b7937fbe (Caused by NameResolutionError("<urllib3.connection.HTTPSConnection object at 0x000001C430B28910>: Failed to resolve 'fapi.binance.com' ([Errno 11001] getaddrinfo failed)"))

Sat Jul 12 23:03:25 2025 - Erreur : Traceback (most recent call last):
  File "C:\Users\user\AppData\Local\Programs\Python\Python310\lib\site-packages\urllib3\connection.py", line 198, in _new_conn
    sock = connection.create_connection(
  File "C:\Users\user\AppData\Local\Programs\Python\Python310\lib\site-packages\urllib3\util\connection.py", line 60, in create_connection
    for res in socket.getaddrinfo(host, port, family, socket.SOCK_STREAM):
  File "C:\Users\user\AppData\Local\Programs\Python\Python310\lib\socket.py", line 955, in getaddrinfo
    for res in _socket.getaddrinfo(host, port, family, type, proto, flags):
socket.gaierror: [Errno 11001] getaddrinfo failed

The above exception was the direct cause of the following exception:

Traceback (most recent call last):
  File "C:\Users\user\AppData\Local\Programs\Python\Python310\lib\site-packages\urllib3\connectionpool.py", line 787, in urlopen
    response = self._make_request(
  File "C:\Users\user\AppData\Local\Programs\Python\Python310\lib\site-packages\urllib3\connectionpool.py", line 488, in _make_request
    raise new_e
  File "C:\Users\user\AppData\Local\Programs\Python\Python310\lib\site-packages\urllib3\connectionpool.py", line 464, in _make_request
    self._validate_conn(conn)
  File "C:\Users\user\AppData\Local\Programs\Python\Python310\lib\site-packages\urllib3\connectionpool.py", line 1093, in _validate_conn
    conn.connect()
  File "C:\Users\user\AppData\Local\Programs\Python\Python310\lib\site-packages\urllib3\connection.py", line 704, in connect
    self.sock = sock = self._new_conn()
  File "C:\Users\user\AppData\Local\Programs\Python\Python310\lib\site-packages\urllib3\connection.py", line 205, in _new_conn
    raise NameResolutionError(self.host, self, e) from e
urllib3.exceptions.NameResolutionError: <urllib3.connection.HTTPSConnection object at 0x000001C430B70E20>: Failed to resolve 'fapi.binance.com' ([Errno 11001] getaddrinfo failed)

The above exception was the direct cause of the following exception:

Traceback (most recent call last):
  File "C:\Users\user\AppData\Local\Programs\Python\Python310\lib\site-packages\requests\adapters.py", line 667, in send
    resp = conn.urlopen(
  File "C:\Users\user\AppData\Local\Programs\Python\Python310\lib\site-packages\urllib3\connectionpool.py", line 841, in urlopen
    retries = retries.increment(
  File "C:\Users\user\AppData\Local\Programs\Python\Python310\lib\site-packages\urllib3\util\retry.py", line 519, in increment
    raise MaxRetryError(_pool, url, reason) from reason  # type: ignore[arg-type]
urllib3.exceptions.MaxRetryError: HTTPSConnectionPool(host='fapi.binance.com', port=443): Max retries exceeded with url: /fapi/v3/positionRisk?recvWindow=10000&symbol=ALGOUSDT&timestamp=1752354205417&signature=c54920fba9f95ab53f3ba30b892c812f977f9f57620e0991831b36acc6f518f3 (Caused by NameResolutionError("<urllib3.connection.HTTPSConnection object at 0x000001C430B70E20>: Failed to resolve 'fapi.binance.com' ([Errno 11001] getaddrinfo failed)"))

During handling of the above exception, another exception occurred:

Traceback (most recent call last):
  File "D:\admin\MES PROJETS\Bot de trading\core\trade_executor.py", line 334, in cancel_all_open_orders_if_no_position
    positions = client.futures_position_information(symbol=symbol)
  File "C:\Users\user\AppData\Local\Programs\Python\Python310\lib\site-packages\binance\client.py", line 7835, in futures_position_information
    return self._request_futures_api("get", "positionRisk", True, 3, data=params)
  File "C:\Users\user\AppData\Local\Programs\Python\Python310\lib\site-packages\binance\client.py", line 126, in _request_futures_api
    return self._request(method, uri, signed, force_params, **kwargs)
  File "C:\Users\user\AppData\Local\Programs\Python\Python310\lib\site-packages\binance\client.py", line 88, in _request
    self.response = getattr(self.session, method)(uri, headers=headers, data=data, **kwargs)
  File "C:\Users\user\AppData\Local\Programs\Python\Python310\lib\site-packages\requests\sessions.py", line 602, in get
    return self.request("GET", url, **kwargs)
  File "C:\Users\user\AppData\Local\Programs\Python\Python310\lib\site-packages\requests\sessions.py", line 589, in request
    resp = self.send(prep, **send_kwargs)
  File "C:\Users\user\AppData\Local\Programs\Python\Python310\lib\site-packages\requests\sessions.py", line 703, in send
    r = adapter.send(request, **kwargs)
  File "C:\Users\user\AppData\Local\Programs\Python\Python310\lib\site-packages\requests\adapters.py", line 700, in send
    raise ConnectionError(e, request=request)
requests.exceptions.ConnectionError: HTTPSConnectionPool(host='fapi.binance.com', port=443): Max retries exceeded with url: /fapi/v3/positionRisk?recvWindow=10000&symbol=ALGOUSDT&timestamp=1752354205417&signature=c54920fba9f95ab53f3ba30b892c812f977f9f57620e0991831b36acc6f518f3 (Caused by NameResolutionError("<urllib3.connection.HTTPSConnection object at 0x000001C430B70E20>: Failed to resolve 'fapi.binance.com' ([Errno 11001] getaddrinfo failed)"))

Sat Jul 12 23:03:35 2025 - Erreur : Traceback (most recent call last):
  File "C:\Users\user\AppData\Local\Programs\Python\Python310\lib\site-packages\urllib3\connection.py", line 198, in _new_conn
    sock = connection.create_connection(
  File "C:\Users\user\AppData\Local\Programs\Python\Python310\lib\site-packages\urllib3\util\connection.py", line 60, in create_connection
    for res in socket.getaddrinfo(host, port, family, socket.SOCK_STREAM):
  File "C:\Users\user\AppData\Local\Programs\Python\Python310\lib\socket.py", line 955, in getaddrinfo
    for res in _socket.getaddrinfo(host, port, family, type, proto, flags):
socket.gaierror: [Errno 11001] getaddrinfo failed

The above exception was the direct cause of the following exception:

Traceback (most recent call last):
  File "C:\Users\user\AppData\Local\Programs\Python\Python310\lib\site-packages\urllib3\connectionpool.py", line 787, in urlopen
    response = self._make_request(
  File "C:\Users\user\AppData\Local\Programs\Python\Python310\lib\site-packages\urllib3\connectionpool.py", line 488, in _make_request
    raise new_e
  File "C:\Users\user\AppData\Local\Programs\Python\Python310\lib\site-packages\urllib3\connectionpool.py", line 464, in _make_request
    self._validate_conn(conn)
  File "C:\Users\user\AppData\Local\Programs\Python\Python310\lib\site-packages\urllib3\connectionpool.py", line 1093, in _validate_conn
    conn.connect()
  File "C:\Users\user\AppData\Local\Programs\Python\Python310\lib\site-packages\urllib3\connection.py", line 704, in connect
    self.sock = sock = self._new_conn()
  File "C:\Users\user\AppData\Local\Programs\Python\Python310\lib\site-packages\urllib3\connection.py", line 205, in _new_conn
    raise NameResolutionError(self.host, self, e) from e
urllib3.exceptions.NameResolutionError: <urllib3.connection.HTTPSConnection object at 0x000001C430B4D3F0>: Failed to resolve 'fapi.binance.com' ([Errno 11001] getaddrinfo failed)

The above exception was the direct cause of the following exception:

Traceback (most recent call last):
  File "C:\Users\user\AppData\Local\Programs\Python\Python310\lib\site-packages\requests\adapters.py", line 667, in send
    resp = conn.urlopen(
  File "C:\Users\user\AppData\Local\Programs\Python\Python310\lib\site-packages\urllib3\connectionpool.py", line 841, in urlopen
    retries = retries.increment(
  File "C:\Users\user\AppData\Local\Programs\Python\Python310\lib\site-packages\urllib3\util\retry.py", line 519, in increment
    raise MaxRetryError(_pool, url, reason) from reason  # type: ignore[arg-type]
urllib3.exceptions.MaxRetryError: HTTPSConnectionPool(host='fapi.binance.com', port=443): Max retries exceeded with url: /fapi/v3/positionRisk?recvWindow=10000&symbol=ALGOUSDT&timestamp=1752354215438&signature=9b4159730748e3579d3a6f7a6bb75b4f11306c44da2ec9ff7c3af7650f379c7a (Caused by NameResolutionError("<urllib3.connection.HTTPSConnection object at 0x000001C430B4D3F0>: Failed to resolve 'fapi.binance.com' ([Errno 11001] getaddrinfo failed)"))

During handling of the above exception, another exception occurred:

Traceback (most recent call last):
  File "D:\admin\MES PROJETS\Bot de trading\core\trade_executor.py", line 334, in cancel_all_open_orders_if_no_position
    positions = client.futures_position_information(symbol=symbol)
  File "C:\Users\user\AppData\Local\Programs\Python\Python310\lib\site-packages\binance\client.py", line 7835, in futures_position_information
    return self._request_futures_api("get", "positionRisk", True, 3, data=params)
  File "C:\Users\user\AppData\Local\Programs\Python\Python310\lib\site-packages\binance\client.py", line 126, in _request_futures_api
    return self._request(method, uri, signed, force_params, **kwargs)
  File "C:\Users\user\AppData\Local\Programs\Python\Python310\lib\site-packages\binance\client.py", line 88, in _request
    self.response = getattr(self.session, method)(uri, headers=headers, data=data, **kwargs)
  File "C:\Users\user\AppData\Local\Programs\Python\Python310\lib\site-packages\requests\sessions.py", line 602, in get
    return self.request("GET", url, **kwargs)
  File "C:\Users\user\AppData\Local\Programs\Python\Python310\lib\site-packages\requests\sessions.py", line 589, in request
    resp = self.send(prep, **send_kwargs)
  File "C:\Users\user\AppData\Local\Programs\Python\Python310\lib\site-packages\requests\sessions.py", line 703, in send
    r = adapter.send(request, **kwargs)
  File "C:\Users\user\AppData\Local\Programs\Python\Python310\lib\site-packages\requests\adapters.py", line 700, in send
    raise ConnectionError(e, request=request)
requests.exceptions.ConnectionError: HTTPSConnectionPool(host='fapi.binance.com', port=443): Max retries exceeded with url: /fapi/v3/positionRisk?recvWindow=10000&symbol=ALGOUSDT&timestamp=1752354215438&signature=9b4159730748e3579d3a6f7a6bb75b4f11306c44da2ec9ff7c3af7650f379c7a (Caused by NameResolutionError("<urllib3.connection.HTTPSConnection object at 0x000001C430B4D3F0>: Failed to resolve 'fapi.binance.com' ([Errno 11001] getaddrinfo failed)"))

Sat Jul 12 23:03:45 2025 - Erreur : Traceback (most recent call last):
  File "C:\Users\user\AppData\Local\Programs\Python\Python310\lib\site-packages\urllib3\connection.py", line 198, in _new_conn
    sock = connection.create_connection(
  File "C:\Users\user\AppData\Local\Programs\Python\Python310\lib\site-packages\urllib3\util\connection.py", line 60, in create_connection
    for res in socket.getaddrinfo(host, port, family, socket.SOCK_STREAM):
  File "C:\Users\user\AppData\Local\Programs\Python\Python310\lib\socket.py", line 955, in getaddrinfo
    for res in _socket.getaddrinfo(host, port, family, type, proto, flags):
socket.gaierror: [Errno 11001] getaddrinfo failed

The above exception was the direct cause of the following exception:

Traceback (most recent call last):
  File "C:\Users\user\AppData\Local\Programs\Python\Python310\lib\site-packages\urllib3\connectionpool.py", line 787, in urlopen
    response = self._make_request(
  File "C:\Users\user\AppData\Local\Programs\Python\Python310\lib\site-packages\urllib3\connectionpool.py", line 488, in _make_request
    raise new_e
  File "C:\Users\user\AppData\Local\Programs\Python\Python310\lib\site-packages\urllib3\connectionpool.py", line 464, in _make_request
    self._validate_conn(conn)
  File "C:\Users\user\AppData\Local\Programs\Python\Python310\lib\site-packages\urllib3\connectionpool.py", line 1093, in _validate_conn
    conn.connect()
  File "C:\Users\user\AppData\Local\Programs\Python\Python310\lib\site-packages\urllib3\connection.py", line 704, in connect
    self.sock = sock = self._new_conn()
  File "C:\Users\user\AppData\Local\Programs\Python\Python310\lib\site-packages\urllib3\connection.py", line 205, in _new_conn
    raise NameResolutionError(self.host, self, e) from e
urllib3.exceptions.NameResolutionError: <urllib3.connection.HTTPSConnection object at 0x000001C430B4CAC0>: Failed to resolve 'fapi.binance.com' ([Errno 11001] getaddrinfo failed)

The above exception was the direct cause of the following exception:

Traceback (most recent call last):
  File "C:\Users\user\AppData\Local\Programs\Python\Python310\lib\site-packages\requests\adapters.py", line 667, in send
    resp = conn.urlopen(
  File "C:\Users\user\AppData\Local\Programs\Python\Python310\lib\site-packages\urllib3\connectionpool.py", line 841, in urlopen
    retries = retries.increment(
  File "C:\Users\user\AppData\Local\Programs\Python\Python310\lib\site-packages\urllib3\util\retry.py", line 519, in increment
    raise MaxRetryError(_pool, url, reason) from reason  # type: ignore[arg-type]
urllib3.exceptions.MaxRetryError: HTTPSConnectionPool(host='fapi.binance.com', port=443): Max retries exceeded with url: /fapi/v3/positionRisk?recvWindow=10000&symbol=ALGOUSDT&timestamp=1752354225453&signature=2ae615fac2860573823e656ffdd169579ffba928664fcb1f844cf09fc7354fed (Caused by NameResolutionError("<urllib3.connection.HTTPSConnection object at 0x000001C430B4CAC0>: Failed to resolve 'fapi.binance.com' ([Errno 11001] getaddrinfo failed)"))

During handling of the above exception, another exception occurred:

Traceback (most recent call last):
  File "D:\admin\MES PROJETS\Bot de trading\core\trade_executor.py", line 334, in cancel_all_open_orders_if_no_position
    positions = client.futures_position_information(symbol=symbol)
  File "C:\Users\user\AppData\Local\Programs\Python\Python310\lib\site-packages\binance\client.py", line 7835, in futures_position_information
    return self._request_futures_api("get", "positionRisk", True, 3, data=params)
  File "C:\Users\user\AppData\Local\Programs\Python\Python310\lib\site-packages\binance\client.py", line 126, in _request_futures_api
    return self._request(method, uri, signed, force_params, **kwargs)
  File "C:\Users\user\AppData\Local\Programs\Python\Python310\lib\site-packages\binance\client.py", line 88, in _request
    self.response = getattr(self.session, method)(uri, headers=headers, data=data, **kwargs)
  File "C:\Users\user\AppData\Local\Programs\Python\Python310\lib\site-packages\requests\sessions.py", line 602, in get
    return self.request("GET", url, **kwargs)
  File "C:\Users\user\AppData\Local\Programs\Python\Python310\lib\site-packages\requests\sessions.py", line 589, in request
    resp = self.send(prep, **send_kwargs)
  File "C:\Users\user\AppData\Local\Programs\Python\Python310\lib\site-packages\requests\sessions.py", line 703, in send
    r = adapter.send(request, **kwargs)
  File "C:\Users\user\AppData\Local\Programs\Python\Python310\lib\site-packages\requests\adapters.py", line 700, in send
    raise ConnectionError(e, request=request)
requests.exceptions.ConnectionError: HTTPSConnectionPool(host='fapi.binance.com', port=443): Max retries exceeded with url: /fapi/v3/positionRisk?recvWindow=10000&symbol=ALGOUSDT&timestamp=1752354225453&signature=2ae615fac2860573823e656ffdd169579ffba928664fcb1f844cf09fc7354fed (Caused by NameResolutionError("<urllib3.connection.HTTPSConnection object at 0x000001C430B4CAC0>: Failed to resolve 'fapi.binance.com' ([Errno 11001] getaddrinfo failed)"))

Sat Jul 12 23:03:55 2025 - Erreur : Traceback (most recent call last):
  File "C:\Users\user\AppData\Local\Programs\Python\Python310\lib\site-packages\urllib3\connection.py", line 198, in _new_conn
    sock = connection.create_connection(
  File "C:\Users\user\AppData\Local\Programs\Python\Python310\lib\site-packages\urllib3\util\connection.py", line 60, in create_connection
    for res in socket.getaddrinfo(host, port, family, socket.SOCK_STREAM):
  File "C:\Users\user\AppData\Local\Programs\Python\Python310\lib\socket.py", line 955, in getaddrinfo
    for res in _socket.getaddrinfo(host, port, family, type, proto, flags):
socket.gaierror: [Errno 11001] getaddrinfo failed

The above exception was the direct cause of the following exception:

Traceback (most recent call last):
  File "C:\Users\user\AppData\Local\Programs\Python\Python310\lib\site-packages\urllib3\connectionpool.py", line 787, in urlopen
    response = self._make_request(
  File "C:\Users\user\AppData\Local\Programs\Python\Python310\lib\site-packages\urllib3\connectionpool.py", line 488, in _make_request
    raise new_e
  File "C:\Users\user\AppData\Local\Programs\Python\Python310\lib\site-packages\urllib3\connectionpool.py", line 464, in _make_request
    self._validate_conn(conn)
  File "C:\Users\user\AppData\Local\Programs\Python\Python310\lib\site-packages\urllib3\connectionpool.py", line 1093, in _validate_conn
    conn.connect()
  File "C:\Users\user\AppData\Local\Programs\Python\Python310\lib\site-packages\urllib3\connection.py", line 704, in connect
    self.sock = sock = self._new_conn()
  File "C:\Users\user\AppData\Local\Programs\Python\Python310\lib\site-packages\urllib3\connection.py", line 205, in _new_conn
    raise NameResolutionError(self.host, self, e) from e
urllib3.exceptions.NameResolutionError: <urllib3.connection.HTTPSConnection object at 0x000001C430AFED70>: Failed to resolve 'fapi.binance.com' ([Errno 11001] getaddrinfo failed)

The above exception was the direct cause of the following exception:

Traceback (most recent call last):
  File "C:\Users\user\AppData\Local\Programs\Python\Python310\lib\site-packages\requests\adapters.py", line 667, in send
    resp = conn.urlopen(
  File "C:\Users\user\AppData\Local\Programs\Python\Python310\lib\site-packages\urllib3\connectionpool.py", line 841, in urlopen
    retries = retries.increment(
  File "C:\Users\user\AppData\Local\Programs\Python\Python310\lib\site-packages\urllib3\util\retry.py", line 519, in increment
    raise MaxRetryError(_pool, url, reason) from reason  # type: ignore[arg-type]
urllib3.exceptions.MaxRetryError: HTTPSConnectionPool(host='fapi.binance.com', port=443): Max retries exceeded with url: /fapi/v3/positionRisk?recvWindow=10000&symbol=ALGOUSDT&timestamp=1752354235460&signature=a7b11064b5fc555d68de6ddf5ef37dac0b2a504f2b2e519b9ee030733b29433c (Caused by NameResolutionError("<urllib3.connection.HTTPSConnection object at 0x000001C430AFED70>: Failed to resolve 'fapi.binance.com' ([Errno 11001] getaddrinfo failed)"))

During handling of the above exception, another exception occurred:

Traceback (most recent call last):
  File "D:\admin\MES PROJETS\Bot de trading\core\trade_executor.py", line 334, in cancel_all_open_orders_if_no_position
    positions = client.futures_position_information(symbol=symbol)
  File "C:\Users\user\AppData\Local\Programs\Python\Python310\lib\site-packages\binance\client.py", line 7835, in futures_position_information
    return self._request_futures_api("get", "positionRisk", True, 3, data=params)
  File "C:\Users\user\AppData\Local\Programs\Python\Python310\lib\site-packages\binance\client.py", line 126, in _request_futures_api
    return self._request(method, uri, signed, force_params, **kwargs)
  File "C:\Users\user\AppData\Local\Programs\Python\Python310\lib\site-packages\binance\client.py", line 88, in _request
    self.response = getattr(self.session, method)(uri, headers=headers, data=data, **kwargs)
  File "C:\Users\user\AppData\Local\Programs\Python\Python310\lib\site-packages\requests\sessions.py", line 602, in get
    return self.request("GET", url, **kwargs)
  File "C:\Users\user\AppData\Local\Programs\Python\Python310\lib\site-packages\requests\sessions.py", line 589, in request
    resp = self.send(prep, **send_kwargs)
  File "C:\Users\user\AppData\Local\Programs\Python\Python310\lib\site-packages\requests\sessions.py", line 703, in send
    r = adapter.send(request, **kwargs)
  File "C:\Users\user\AppData\Local\Programs\Python\Python310\lib\site-packages\requests\adapters.py", line 700, in send
    raise ConnectionError(e, request=request)
requests.exceptions.ConnectionError: HTTPSConnectionPool(host='fapi.binance.com', port=443): Max retries exceeded with url: /fapi/v3/positionRisk?recvWindow=10000&symbol=ALGOUSDT&timestamp=1752354235460&signature=a7b11064b5fc555d68de6ddf5ef37dac0b2a504f2b2e519b9ee030733b29433c (Caused by NameResolutionError("<urllib3.connection.HTTPSConnection object at 0x000001C430AFED70>: Failed to resolve 'fapi.binance.com' ([Errno 11001] getaddrinfo failed)"))

Sat Jul 12 23:04:05 2025 - Erreur : Traceback (most recent call last):
  File "C:\Users\user\AppData\Local\Programs\Python\Python310\lib\site-packages\urllib3\connection.py", line 198, in _new_conn
    sock = connection.create_connection(
  File "C:\Users\user\AppData\Local\Programs\Python\Python310\lib\site-packages\urllib3\util\connection.py", line 60, in create_connection
    for res in socket.getaddrinfo(host, port, family, socket.SOCK_STREAM):
  File "C:\Users\user\AppData\Local\Programs\Python\Python310\lib\socket.py", line 955, in getaddrinfo
    for res in _socket.getaddrinfo(host, port, family, type, proto, flags):
socket.gaierror: [Errno 11001] getaddrinfo failed

The above exception was the direct cause of the following exception:

Traceback (most recent call last):
  File "C:\Users\user\AppData\Local\Programs\Python\Python310\lib\site-packages\urllib3\connectionpool.py", line 787, in urlopen
    response = self._make_request(
  File "C:\Users\user\AppData\Local\Programs\Python\Python310\lib\site-packages\urllib3\connectionpool.py", line 488, in _make_request
    raise new_e
  File "C:\Users\user\AppData\Local\Programs\Python\Python310\lib\site-packages\urllib3\connectionpool.py", line 464, in _make_request
    self._validate_conn(conn)
  File "C:\Users\user\AppData\Local\Programs\Python\Python310\lib\site-packages\urllib3\connectionpool.py", line 1093, in _validate_conn
    conn.connect()
  File "C:\Users\user\AppData\Local\Programs\Python\Python310\lib\site-packages\urllib3\connection.py", line 704, in connect
    self.sock = sock = self._new_conn()
  File "C:\Users\user\AppData\Local\Programs\Python\Python310\lib\site-packages\urllib3\connection.py", line 205, in _new_conn
    raise NameResolutionError(self.host, self, e) from e
urllib3.exceptions.NameResolutionError: <urllib3.connection.HTTPSConnection object at 0x000001C430AFC160>: Failed to resolve 'fapi.binance.com' ([Errno 11001] getaddrinfo failed)

The above exception was the direct cause of the following exception:

Traceback (most recent call last):
  File "C:\Users\user\AppData\Local\Programs\Python\Python310\lib\site-packages\requests\adapters.py", line 667, in send
    resp = conn.urlopen(
  File "C:\Users\user\AppData\Local\Programs\Python\Python310\lib\site-packages\urllib3\connectionpool.py", line 841, in urlopen
    retries = retries.increment(
  File "C:\Users\user\AppData\Local\Programs\Python\Python310\lib\site-packages\urllib3\util\retry.py", line 519, in increment
    raise MaxRetryError(_pool, url, reason) from reason  # type: ignore[arg-type]
urllib3.exceptions.MaxRetryError: HTTPSConnectionPool(host='fapi.binance.com', port=443): Max retries exceeded with url: /fapi/v3/positionRisk?recvWindow=10000&symbol=ALGOUSDT&timestamp=1752354245478&signature=a62671b9b99c08d5edc6f0cfce9b33913504938ed68a8bc2abfd3e0feee7cb91 (Caused by NameResolutionError("<urllib3.connection.HTTPSConnection object at 0x000001C430AFC160>: Failed to resolve 'fapi.binance.com' ([Errno 11001] getaddrinfo failed)"))

During handling of the above exception, another exception occurred:

Traceback (most recent call last):
  File "D:\admin\MES PROJETS\Bot de trading\core\trade_executor.py", line 334, in cancel_all_open_orders_if_no_position
    positions = client.futures_position_information(symbol=symbol)
  File "C:\Users\user\AppData\Local\Programs\Python\Python310\lib\site-packages\binance\client.py", line 7835, in futures_position_information
    return self._request_futures_api("get", "positionRisk", True, 3, data=params)
  File "C:\Users\user\AppData\Local\Programs\Python\Python310\lib\site-packages\binance\client.py", line 126, in _request_futures_api
    return self._request(method, uri, signed, force_params, **kwargs)
  File "C:\Users\user\AppData\Local\Programs\Python\Python310\lib\site-packages\binance\client.py", line 88, in _request
    self.response = getattr(self.session, method)(uri, headers=headers, data=data, **kwargs)
  File "C:\Users\user\AppData\Local\Programs\Python\Python310\lib\site-packages\requests\sessions.py", line 602, in get
    return self.request("GET", url, **kwargs)
  File "C:\Users\user\AppData\Local\Programs\Python\Python310\lib\site-packages\requests\sessions.py", line 589, in request
    resp = self.send(prep, **send_kwargs)
  File "C:\Users\user\AppData\Local\Programs\Python\Python310\lib\site-packages\requests\sessions.py", line 703, in send
    r = adapter.send(request, **kwargs)
  File "C:\Users\user\AppData\Local\Programs\Python\Python310\lib\site-packages\requests\adapters.py", line 700, in send
    raise ConnectionError(e, request=request)
requests.exceptions.ConnectionError: HTTPSConnectionPool(host='fapi.binance.com', port=443): Max retries exceeded with url: /fapi/v3/positionRisk?recvWindow=10000&symbol=ALGOUSDT&timestamp=1752354245478&signature=a62671b9b99c08d5edc6f0cfce9b33913504938ed68a8bc2abfd3e0feee7cb91 (Caused by NameResolutionError("<urllib3.connection.HTTPSConnection object at 0x000001C430AFC160>: Failed to resolve 'fapi.binance.com' ([Errno 11001] getaddrinfo failed)"))

Sat Jul 12 23:04:15 2025 - Erreur : Traceback (most recent call last):
  File "C:\Users\user\AppData\Local\Programs\Python\Python310\lib\site-packages\urllib3\connection.py", line 198, in _new_conn
    sock = connection.create_connection(
  File "C:\Users\user\AppData\Local\Programs\Python\Python310\lib\site-packages\urllib3\util\connection.py", line 60, in create_connection
    for res in socket.getaddrinfo(host, port, family, socket.SOCK_STREAM):
  File "C:\Users\user\AppData\Local\Programs\Python\Python310\lib\socket.py", line 955, in getaddrinfo
    for res in _socket.getaddrinfo(host, port, family, type, proto, flags):
socket.gaierror: [Errno 11001] getaddrinfo failed

The above exception was the direct cause of the following exception:

Traceback (most recent call last):
  File "C:\Users\user\AppData\Local\Programs\Python\Python310\lib\site-packages\urllib3\connectionpool.py", line 787, in urlopen
    response = self._make_request(
  File "C:\Users\user\AppData\Local\Programs\Python\Python310\lib\site-packages\urllib3\connectionpool.py", line 488, in _make_request
    raise new_e
  File "C:\Users\user\AppData\Local\Programs\Python\Python310\lib\site-packages\urllib3\connectionpool.py", line 464, in _make_request
    self._validate_conn(conn)
  File "C:\Users\user\AppData\Local\Programs\Python\Python310\lib\site-packages\urllib3\connectionpool.py", line 1093, in _validate_conn
    conn.connect()
  File "C:\Users\user\AppData\Local\Programs\Python\Python310\lib\site-packages\urllib3\connection.py", line 704, in connect
    self.sock = sock = self._new_conn()
  File "C:\Users\user\AppData\Local\Programs\Python\Python310\lib\site-packages\urllib3\connection.py", line 205, in _new_conn
    raise NameResolutionError(self.host, self, e) from e
urllib3.exceptions.NameResolutionError: <urllib3.connection.HTTPSConnection object at 0x000001C430AEC370>: Failed to resolve 'fapi.binance.com' ([Errno 11001] getaddrinfo failed)

The above exception was the direct cause of the following exception:

Traceback (most recent call last):
  File "C:\Users\user\AppData\Local\Programs\Python\Python310\lib\site-packages\requests\adapters.py", line 667, in send
    resp = conn.urlopen(
  File "C:\Users\user\AppData\Local\Programs\Python\Python310\lib\site-packages\urllib3\connectionpool.py", line 841, in urlopen
    retries = retries.increment(
  File "C:\Users\user\AppData\Local\Programs\Python\Python310\lib\site-packages\urllib3\util\retry.py", line 519, in increment
    raise MaxRetryError(_pool, url, reason) from reason  # type: ignore[arg-type]
urllib3.exceptions.MaxRetryError: HTTPSConnectionPool(host='fapi.binance.com', port=443): Max retries exceeded with url: /fapi/v3/positionRisk?recvWindow=10000&symbol=ALGOUSDT&timestamp=1752354255514&signature=722e15d0a8af815aac917087eb2f6651088f164a30a2de17df9945095ef02045 (Caused by NameResolutionError("<urllib3.connection.HTTPSConnection object at 0x000001C430AEC370>: Failed to resolve 'fapi.binance.com' ([Errno 11001] getaddrinfo failed)"))

During handling of the above exception, another exception occurred:

Traceback (most recent call last):
  File "D:\admin\MES PROJETS\Bot de trading\core\trade_executor.py", line 334, in cancel_all_open_orders_if_no_position
    positions = client.futures_position_information(symbol=symbol)
  File "C:\Users\user\AppData\Local\Programs\Python\Python310\lib\site-packages\binance\client.py", line 7835, in futures_position_information
    return self._request_futures_api("get", "positionRisk", True, 3, data=params)
  File "C:\Users\user\AppData\Local\Programs\Python\Python310\lib\site-packages\binance\client.py", line 126, in _request_futures_api
    return self._request(method, uri, signed, force_params, **kwargs)
  File "C:\Users\user\AppData\Local\Programs\Python\Python310\lib\site-packages\binance\client.py", line 88, in _request
    self.response = getattr(self.session, method)(uri, headers=headers, data=data, **kwargs)
  File "C:\Users\user\AppData\Local\Programs\Python\Python310\lib\site-packages\requests\sessions.py", line 602, in get
    return self.request("GET", url, **kwargs)
  File "C:\Users\user\AppData\Local\Programs\Python\Python310\lib\site-packages\requests\sessions.py", line 589, in request
    resp = self.send(prep, **send_kwargs)
  File "C:\Users\user\AppData\Local\Programs\Python\Python310\lib\site-packages\requests\sessions.py", line 703, in send
    r = adapter.send(request, **kwargs)
  File "C:\Users\user\AppData\Local\Programs\Python\Python310\lib\site-packages\requests\adapters.py", line 700, in send
    raise ConnectionError(e, request=request)
requests.exceptions.ConnectionError: HTTPSConnectionPool(host='fapi.binance.com', port=443): Max retries exceeded with url: /fapi/v3/positionRisk?recvWindow=10000&symbol=ALGOUSDT&timestamp=1752354255514&signature=722e15d0a8af815aac917087eb2f6651088f164a30a2de17df9945095ef02045 (Caused by NameResolutionError("<urllib3.connection.HTTPSConnection object at 0x000001C430AEC370>: Failed to resolve 'fapi.binance.com' ([Errno 11001] getaddrinfo failed)"))

Sat Jul 12 23:04:25 2025 - Erreur : Traceback (most recent call last):
  File "C:\Users\user\AppData\Local\Programs\Python\Python310\lib\site-packages\urllib3\connection.py", line 198, in _new_conn
    sock = connection.create_connection(
  File "C:\Users\user\AppData\Local\Programs\Python\Python310\lib\site-packages\urllib3\util\connection.py", line 60, in create_connection
    for res in socket.getaddrinfo(host, port, family, socket.SOCK_STREAM):
  File "C:\Users\user\AppData\Local\Programs\Python\Python310\lib\socket.py", line 955, in getaddrinfo
    for res in _socket.getaddrinfo(host, port, family, type, proto, flags):
socket.gaierror: [Errno 11001] getaddrinfo failed

The above exception was the direct cause of the following exception:

Traceback (most recent call last):
  File "C:\Users\user\AppData\Local\Programs\Python\Python310\lib\site-packages\urllib3\connectionpool.py", line 787, in urlopen
    response = self._make_request(
  File "C:\Users\user\AppData\Local\Programs\Python\Python310\lib\site-packages\urllib3\connectionpool.py", line 488, in _make_request
    raise new_e
  File "C:\Users\user\AppData\Local\Programs\Python\Python310\lib\site-packages\urllib3\connectionpool.py", line 464, in _make_request
    self._validate_conn(conn)
  File "C:\Users\user\AppData\Local\Programs\Python\Python310\lib\site-packages\urllib3\connectionpool.py", line 1093, in _validate_conn
    conn.connect()
  File "C:\Users\user\AppData\Local\Programs\Python\Python310\lib\site-packages\urllib3\connection.py", line 704, in connect
    self.sock = sock = self._new_conn()
  File "C:\Users\user\AppData\Local\Programs\Python\Python310\lib\site-packages\urllib3\connection.py", line 205, in _new_conn
    raise NameResolutionError(self.host, self, e) from e
urllib3.exceptions.NameResolutionError: <urllib3.connection.HTTPSConnection object at 0x000001C430691F60>: Failed to resolve 'fapi.binance.com' ([Errno 11001] getaddrinfo failed)

The above exception was the direct cause of the following exception:

Traceback (most recent call last):
  File "C:\Users\user\AppData\Local\Programs\Python\Python310\lib\site-packages\requests\adapters.py", line 667, in send
    resp = conn.urlopen(
  File "C:\Users\user\AppData\Local\Programs\Python\Python310\lib\site-packages\urllib3\connectionpool.py", line 841, in urlopen
    retries = retries.increment(
  File "C:\Users\user\AppData\Local\Programs\Python\Python310\lib\site-packages\urllib3\util\retry.py", line 519, in increment
    raise MaxRetryError(_pool, url, reason) from reason  # type: ignore[arg-type]
urllib3.exceptions.MaxRetryError: HTTPSConnectionPool(host='fapi.binance.com', port=443): Max retries exceeded with url: /fapi/v3/positionRisk?recvWindow=10000&symbol=ALGOUSDT&timestamp=1752354265528&signature=a8c25752608d0d906a6e0b2a436e1e5e71949d28d17575d1db6f47d8103cfe39 (Caused by NameResolutionError("<urllib3.connection.HTTPSConnection object at 0x000001C430691F60>: Failed to resolve 'fapi.binance.com' ([Errno 11001] getaddrinfo failed)"))

During handling of the above exception, another exception occurred:

Traceback (most recent call last):
  File "D:\admin\MES PROJETS\Bot de trading\core\trade_executor.py", line 334, in cancel_all_open_orders_if_no_position
    positions = client.futures_position_information(symbol=symbol)
  File "C:\Users\user\AppData\Local\Programs\Python\Python310\lib\site-packages\binance\client.py", line 7835, in futures_position_information
    return self._request_futures_api("get", "positionRisk", True, 3, data=params)
  File "C:\Users\user\AppData\Local\Programs\Python\Python310\lib\site-packages\binance\client.py", line 126, in _request_futures_api
    return self._request(method, uri, signed, force_params, **kwargs)
  File "C:\Users\user\AppData\Local\Programs\Python\Python310\lib\site-packages\binance\client.py", line 88, in _request
    self.response = getattr(self.session, method)(uri, headers=headers, data=data, **kwargs)
  File "C:\Users\user\AppData\Local\Programs\Python\Python310\lib\site-packages\requests\sessions.py", line 602, in get
    return self.request("GET", url, **kwargs)
  File "C:\Users\user\AppData\Local\Programs\Python\Python310\lib\site-packages\requests\sessions.py", line 589, in request
    resp = self.send(prep, **send_kwargs)
  File "C:\Users\user\AppData\Local\Programs\Python\Python310\lib\site-packages\requests\sessions.py", line 703, in send
    r = adapter.send(request, **kwargs)
  File "C:\Users\user\AppData\Local\Programs\Python\Python310\lib\site-packages\requests\adapters.py", line 700, in send
    raise ConnectionError(e, request=request)
requests.exceptions.ConnectionError: HTTPSConnectionPool(host='fapi.binance.com', port=443): Max retries exceeded with url: /fapi/v3/positionRisk?recvWindow=10000&symbol=ALGOUSDT&timestamp=1752354265528&signature=a8c25752608d0d906a6e0b2a436e1e5e71949d28d17575d1db6f47d8103cfe39 (Caused by NameResolutionError("<urllib3.connection.HTTPSConnection object at 0x000001C430691F60>: Failed to resolve 'fapi.binance.com' ([Errno 11001] getaddrinfo failed)"))

Sat Jul 12 23:04:35 2025 - Erreur : Traceback (most recent call last):
  File "C:\Users\user\AppData\Local\Programs\Python\Python310\lib\site-packages\urllib3\connection.py", line 198, in _new_conn
    sock = connection.create_connection(
  File "C:\Users\user\AppData\Local\Programs\Python\Python310\lib\site-packages\urllib3\util\connection.py", line 60, in create_connection
    for res in socket.getaddrinfo(host, port, family, socket.SOCK_STREAM):
  File "C:\Users\user\AppData\Local\Programs\Python\Python310\lib\socket.py", line 955, in getaddrinfo
    for res in _socket.getaddrinfo(host, port, family, type, proto, flags):
socket.gaierror: [Errno 11001] getaddrinfo failed

The above exception was the direct cause of the following exception:

Traceback (most recent call last):
  File "C:\Users\user\AppData\Local\Programs\Python\Python310\lib\site-packages\urllib3\connectionpool.py", line 787, in urlopen
    response = self._make_request(
  File "C:\Users\user\AppData\Local\Programs\Python\Python310\lib\site-packages\urllib3\connectionpool.py", line 488, in _make_request
    raise new_e
  File "C:\Users\user\AppData\Local\Programs\Python\Python310\lib\site-packages\urllib3\connectionpool.py", line 464, in _make_request
    self._validate_conn(conn)
  File "C:\Users\user\AppData\Local\Programs\Python\Python310\lib\site-packages\urllib3\connectionpool.py", line 1093, in _validate_conn
    conn.connect()
  File "C:\Users\user\AppData\Local\Programs\Python\Python310\lib\site-packages\urllib3\connection.py", line 704, in connect
    self.sock = sock = self._new_conn()
  File "C:\Users\user\AppData\Local\Programs\Python\Python310\lib\site-packages\urllib3\connection.py", line 205, in _new_conn
    raise NameResolutionError(self.host, self, e) from e
urllib3.exceptions.NameResolutionError: <urllib3.connection.HTTPSConnection object at 0x000001C4306B8F10>: Failed to resolve 'fapi.binance.com' ([Errno 11001] getaddrinfo failed)

The above exception was the direct cause of the following exception:

Traceback (most recent call last):
  File "C:\Users\user\AppData\Local\Programs\Python\Python310\lib\site-packages\requests\adapters.py", line 667, in send
    resp = conn.urlopen(
  File "C:\Users\user\AppData\Local\Programs\Python\Python310\lib\site-packages\urllib3\connectionpool.py", line 841, in urlopen
    retries = retries.increment(
  File "C:\Users\user\AppData\Local\Programs\Python\Python310\lib\site-packages\urllib3\util\retry.py", line 519, in increment
    raise MaxRetryError(_pool, url, reason) from reason  # type: ignore[arg-type]
urllib3.exceptions.MaxRetryError: HTTPSConnectionPool(host='fapi.binance.com', port=443): Max retries exceeded with url: /fapi/v3/positionRisk?recvWindow=10000&symbol=ALGOUSDT&timestamp=1752354275543&signature=9148085f70e72941f7ff9f061aa32b165140c583eeb52c0ab5605671cdeea98e (Caused by NameResolutionError("<urllib3.connection.HTTPSConnection object at 0x000001C4306B8F10>: Failed to resolve 'fapi.binance.com' ([Errno 11001] getaddrinfo failed)"))

During handling of the above exception, another exception occurred:

Traceback (most recent call last):
  File "D:\admin\MES PROJETS\Bot de trading\core\trade_executor.py", line 334, in cancel_all_open_orders_if_no_position
    positions = client.futures_position_information(symbol=symbol)
  File "C:\Users\user\AppData\Local\Programs\Python\Python310\lib\site-packages\binance\client.py", line 7835, in futures_position_information
    return self._request_futures_api("get", "positionRisk", True, 3, data=params)
  File "C:\Users\user\AppData\Local\Programs\Python\Python310\lib\site-packages\binance\client.py", line 126, in _request_futures_api
    return self._request(method, uri, signed, force_params, **kwargs)
  File "C:\Users\user\AppData\Local\Programs\Python\Python310\lib\site-packages\binance\client.py", line 88, in _request
    self.response = getattr(self.session, method)(uri, headers=headers, data=data, **kwargs)
  File "C:\Users\user\AppData\Local\Programs\Python\Python310\lib\site-packages\requests\sessions.py", line 602, in get
    return self.request("GET", url, **kwargs)
  File "C:\Users\user\AppData\Local\Programs\Python\Python310\lib\site-packages\requests\sessions.py", line 589, in request
    resp = self.send(prep, **send_kwargs)
  File "C:\Users\user\AppData\Local\Programs\Python\Python310\lib\site-packages\requests\sessions.py", line 703, in send
    r = adapter.send(request, **kwargs)
  File "C:\Users\user\AppData\Local\Programs\Python\Python310\lib\site-packages\requests\adapters.py", line 700, in send
    raise ConnectionError(e, request=request)
requests.exceptions.ConnectionError: HTTPSConnectionPool(host='fapi.binance.com', port=443): Max retries exceeded with url: /fapi/v3/positionRisk?recvWindow=10000&symbol=ALGOUSDT&timestamp=1752354275543&signature=9148085f70e72941f7ff9f061aa32b165140c583eeb52c0ab5605671cdeea98e (Caused by NameResolutionError("<urllib3.connection.HTTPSConnection object at 0x000001C4306B8F10>: Failed to resolve 'fapi.binance.com' ([Errno 11001] getaddrinfo failed)"))

Sat Jul 12 23:04:45 2025 - Erreur : Traceback (most recent call last):
  File "C:\Users\user\AppData\Local\Programs\Python\Python310\lib\site-packages\urllib3\connection.py", line 198, in _new_conn
    sock = connection.create_connection(
  File "C:\Users\user\AppData\Local\Programs\Python\Python310\lib\site-packages\urllib3\util\connection.py", line 60, in create_connection
    for res in socket.getaddrinfo(host, port, family, socket.SOCK_STREAM):
  File "C:\Users\user\AppData\Local\Programs\Python\Python310\lib\socket.py", line 955, in getaddrinfo
    for res in _socket.getaddrinfo(host, port, family, type, proto, flags):
socket.gaierror: [Errno 11001] getaddrinfo failed

The above exception was the direct cause of the following exception:

Traceback (most recent call last):
  File "C:\Users\user\AppData\Local\Programs\Python\Python310\lib\site-packages\urllib3\connectionpool.py", line 787, in urlopen
    response = self._make_request(
  File "C:\Users\user\AppData\Local\Programs\Python\Python310\lib\site-packages\urllib3\connectionpool.py", line 488, in _make_request
    raise new_e
  File "C:\Users\user\AppData\Local\Programs\Python\Python310\lib\site-packages\urllib3\connectionpool.py", line 464, in _make_request
    self._validate_conn(conn)
  File "C:\Users\user\AppData\Local\Programs\Python\Python310\lib\site-packages\urllib3\connectionpool.py", line 1093, in _validate_conn
    conn.connect()
  File "C:\Users\user\AppData\Local\Programs\Python\Python310\lib\site-packages\urllib3\connection.py", line 704, in connect
    self.sock = sock = self._new_conn()
  File "C:\Users\user\AppData\Local\Programs\Python\Python310\lib\site-packages\urllib3\connection.py", line 205, in _new_conn
    raise NameResolutionError(self.host, self, e) from e
urllib3.exceptions.NameResolutionError: <urllib3.connection.HTTPSConnection object at 0x000001C4306BAF80>: Failed to resolve 'fapi.binance.com' ([Errno 11001] getaddrinfo failed)

The above exception was the direct cause of the following exception:

Traceback (most recent call last):
  File "C:\Users\user\AppData\Local\Programs\Python\Python310\lib\site-packages\requests\adapters.py", line 667, in send
    resp = conn.urlopen(
  File "C:\Users\user\AppData\Local\Programs\Python\Python310\lib\site-packages\urllib3\connectionpool.py", line 841, in urlopen
    retries = retries.increment(
  File "C:\Users\user\AppData\Local\Programs\Python\Python310\lib\site-packages\urllib3\util\retry.py", line 519, in increment
    raise MaxRetryError(_pool, url, reason) from reason  # type: ignore[arg-type]
urllib3.exceptions.MaxRetryError: HTTPSConnectionPool(host='fapi.binance.com', port=443): Max retries exceeded with url: /fapi/v3/positionRisk?recvWindow=10000&symbol=ALGOUSDT&timestamp=1752354285556&signature=c6de4f6438e745e5bcaf86929d2483cfe850075c6d2d0925407f47efc9cf8bbe (Caused by NameResolutionError("<urllib3.connection.HTTPSConnection object at 0x000001C4306BAF80>: Failed to resolve 'fapi.binance.com' ([Errno 11001] getaddrinfo failed)"))

During handling of the above exception, another exception occurred:

Traceback (most recent call last):
  File "D:\admin\MES PROJETS\Bot de trading\core\trade_executor.py", line 334, in cancel_all_open_orders_if_no_position
    positions = client.futures_position_information(symbol=symbol)
  File "C:\Users\user\AppData\Local\Programs\Python\Python310\lib\site-packages\binance\client.py", line 7835, in futures_position_information
    return self._request_futures_api("get", "positionRisk", True, 3, data=params)
  File "C:\Users\user\AppData\Local\Programs\Python\Python310\lib\site-packages\binance\client.py", line 126, in _request_futures_api
    return self._request(method, uri, signed, force_params, **kwargs)
  File "C:\Users\user\AppData\Local\Programs\Python\Python310\lib\site-packages\binance\client.py", line 88, in _request
    self.response = getattr(self.session, method)(uri, headers=headers, data=data, **kwargs)
  File "C:\Users\user\AppData\Local\Programs\Python\Python310\lib\site-packages\requests\sessions.py", line 602, in get
    return self.request("GET", url, **kwargs)
  File "C:\Users\user\AppData\Local\Programs\Python\Python310\lib\site-packages\requests\sessions.py", line 589, in request
    resp = self.send(prep, **send_kwargs)
  File "C:\Users\user\AppData\Local\Programs\Python\Python310\lib\site-packages\requests\sessions.py", line 703, in send
    r = adapter.send(request, **kwargs)
  File "C:\Users\user\AppData\Local\Programs\Python\Python310\lib\site-packages\requests\adapters.py", line 700, in send
    raise ConnectionError(e, request=request)
requests.exceptions.ConnectionError: HTTPSConnectionPool(host='fapi.binance.com', port=443): Max retries exceeded with url: /fapi/v3/positionRisk?recvWindow=10000&symbol=ALGOUSDT&timestamp=1752354285556&signature=c6de4f6438e745e5bcaf86929d2483cfe850075c6d2d0925407f47efc9cf8bbe (Caused by NameResolutionError("<urllib3.connection.HTTPSConnection object at 0x000001C4306BAF80>: Failed to resolve 'fapi.binance.com' ([Errno 11001] getaddrinfo failed)"))

Sat Jul 12 23:04:55 2025 - Erreur : Traceback (most recent call last):
  File "C:\Users\user\AppData\Local\Programs\Python\Python310\lib\site-packages\urllib3\connection.py", line 198, in _new_conn
    sock = connection.create_connection(
  File "C:\Users\user\AppData\Local\Programs\Python\Python310\lib\site-packages\urllib3\util\connection.py", line 60, in create_connection
    for res in socket.getaddrinfo(host, port, family, socket.SOCK_STREAM):
  File "C:\Users\user\AppData\Local\Programs\Python\Python310\lib\socket.py", line 955, in getaddrinfo
    for res in _socket.getaddrinfo(host, port, family, type, proto, flags):
socket.gaierror: [Errno 11001] getaddrinfo failed

The above exception was the direct cause of the following exception:

Traceback (most recent call last):
  File "C:\Users\user\AppData\Local\Programs\Python\Python310\lib\site-packages\urllib3\connectionpool.py", line 787, in urlopen
    response = self._make_request(
  File "C:\Users\user\AppData\Local\Programs\Python\Python310\lib\site-packages\urllib3\connectionpool.py", line 488, in _make_request
    raise new_e
  File "C:\Users\user\AppData\Local\Programs\Python\Python310\lib\site-packages\urllib3\connectionpool.py", line 464, in _make_request
    self._validate_conn(conn)
  File "C:\Users\user\AppData\Local\Programs\Python\Python310\lib\site-packages\urllib3\connectionpool.py", line 1093, in _validate_conn
    conn.connect()
  File "C:\Users\user\AppData\Local\Programs\Python\Python310\lib\site-packages\urllib3\connection.py", line 704, in connect
    self.sock = sock = self._new_conn()
  File "C:\Users\user\AppData\Local\Programs\Python\Python310\lib\site-packages\urllib3\connection.py", line 205, in _new_conn
    raise NameResolutionError(self.host, self, e) from e
urllib3.exceptions.NameResolutionError: <urllib3.connection.HTTPSConnection object at 0x000001C430AFC3D0>: Failed to resolve 'fapi.binance.com' ([Errno 11001] getaddrinfo failed)

The above exception was the direct cause of the following exception:

Traceback (most recent call last):
  File "C:\Users\user\AppData\Local\Programs\Python\Python310\lib\site-packages\requests\adapters.py", line 667, in send
    resp = conn.urlopen(
  File "C:\Users\user\AppData\Local\Programs\Python\Python310\lib\site-packages\urllib3\connectionpool.py", line 841, in urlopen
    retries = retries.increment(
  File "C:\Users\user\AppData\Local\Programs\Python\Python310\lib\site-packages\urllib3\util\retry.py", line 519, in increment
    raise MaxRetryError(_pool, url, reason) from reason  # type: ignore[arg-type]
urllib3.exceptions.MaxRetryError: HTTPSConnectionPool(host='fapi.binance.com', port=443): Max retries exceeded with url: /fapi/v3/positionRisk?recvWindow=10000&symbol=ALGOUSDT&timestamp=1752354295573&signature=5d1b577c79c75e72d28f081df68ca9fcdb32332867cd74370a84e2c837ad204e (Caused by NameResolutionError("<urllib3.connection.HTTPSConnection object at 0x000001C430AFC3D0>: Failed to resolve 'fapi.binance.com' ([Errno 11001] getaddrinfo failed)"))

During handling of the above exception, another exception occurred:

Traceback (most recent call last):
  File "D:\admin\MES PROJETS\Bot de trading\core\trade_executor.py", line 334, in cancel_all_open_orders_if_no_position
    positions = client.futures_position_information(symbol=symbol)
  File "C:\Users\user\AppData\Local\Programs\Python\Python310\lib\site-packages\binance\client.py", line 7835, in futures_position_information
    return self._request_futures_api("get", "positionRisk", True, 3, data=params)
  File "C:\Users\user\AppData\Local\Programs\Python\Python310\lib\site-packages\binance\client.py", line 126, in _request_futures_api
    return self._request(method, uri, signed, force_params, **kwargs)
  File "C:\Users\user\AppData\Local\Programs\Python\Python310\lib\site-packages\binance\client.py", line 88, in _request
    self.response = getattr(self.session, method)(uri, headers=headers, data=data, **kwargs)
  File "C:\Users\user\AppData\Local\Programs\Python\Python310\lib\site-packages\requests\sessions.py", line 602, in get
    return self.request("GET", url, **kwargs)
  File "C:\Users\user\AppData\Local\Programs\Python\Python310\lib\site-packages\requests\sessions.py", line 589, in request
    resp = self.send(prep, **send_kwargs)
  File "C:\Users\user\AppData\Local\Programs\Python\Python310\lib\site-packages\requests\sessions.py", line 703, in send
    r = adapter.send(request, **kwargs)
  File "C:\Users\user\AppData\Local\Programs\Python\Python310\lib\site-packages\requests\adapters.py", line 700, in send
    raise ConnectionError(e, request=request)
requests.exceptions.ConnectionError: HTTPSConnectionPool(host='fapi.binance.com', port=443): Max retries exceeded with url: /fapi/v3/positionRisk?recvWindow=10000&symbol=ALGOUSDT&timestamp=1752354295573&signature=5d1b577c79c75e72d28f081df68ca9fcdb32332867cd74370a84e2c837ad204e (Caused by NameResolutionError("<urllib3.connection.HTTPSConnection object at 0x000001C430AFC3D0>: Failed to resolve 'fapi.binance.com' ([Errno 11001] getaddrinfo failed)"))

Sat Jul 12 23:05:05 2025 - Erreur : Traceback (most recent call last):
  File "C:\Users\user\AppData\Local\Programs\Python\Python310\lib\site-packages\urllib3\connection.py", line 198, in _new_conn
    sock = connection.create_connection(
  File "C:\Users\user\AppData\Local\Programs\Python\Python310\lib\site-packages\urllib3\util\connection.py", line 60, in create_connection
    for res in socket.getaddrinfo(host, port, family, socket.SOCK_STREAM):
  File "C:\Users\user\AppData\Local\Programs\Python\Python310\lib\socket.py", line 955, in getaddrinfo
    for res in _socket.getaddrinfo(host, port, family, type, proto, flags):
socket.gaierror: [Errno 11001] getaddrinfo failed

The above exception was the direct cause of the following exception:

Traceback (most recent call last):
  File "C:\Users\user\AppData\Local\Programs\Python\Python310\lib\site-packages\urllib3\connectionpool.py", line 787, in urlopen
    response = self._make_request(
  File "C:\Users\user\AppData\Local\Programs\Python\Python310\lib\site-packages\urllib3\connectionpool.py", line 488, in _make_request
    raise new_e
  File "C:\Users\user\AppData\Local\Programs\Python\Python310\lib\site-packages\urllib3\connectionpool.py", line 464, in _make_request
    self._validate_conn(conn)
  File "C:\Users\user\AppData\Local\Programs\Python\Python310\lib\site-packages\urllib3\connectionpool.py", line 1093, in _validate_conn
    conn.connect()
  File "C:\Users\user\AppData\Local\Programs\Python\Python310\lib\site-packages\urllib3\connection.py", line 704, in connect
    self.sock = sock = self._new_conn()
  File "C:\Users\user\AppData\Local\Programs\Python\Python310\lib\site-packages\urllib3\connection.py", line 205, in _new_conn
    raise NameResolutionError(self.host, self, e) from e
urllib3.exceptions.NameResolutionError: <urllib3.connection.HTTPSConnection object at 0x000001C430AFEB00>: Failed to resolve 'fapi.binance.com' ([Errno 11001] getaddrinfo failed)

The above exception was the direct cause of the following exception:

Traceback (most recent call last):
  File "C:\Users\user\AppData\Local\Programs\Python\Python310\lib\site-packages\requests\adapters.py", line 667, in send
    resp = conn.urlopen(
  File "C:\Users\user\AppData\Local\Programs\Python\Python310\lib\site-packages\urllib3\connectionpool.py", line 841, in urlopen
    retries = retries.increment(
  File "C:\Users\user\AppData\Local\Programs\Python\Python310\lib\site-packages\urllib3\util\retry.py", line 519, in increment
    raise MaxRetryError(_pool, url, reason) from reason  # type: ignore[arg-type]
urllib3.exceptions.MaxRetryError: HTTPSConnectionPool(host='fapi.binance.com', port=443): Max retries exceeded with url: /fapi/v3/positionRisk?recvWindow=10000&symbol=ALGOUSDT&timestamp=1752354305592&signature=78b3c424170bc21c7ab84cbe6a3db9d586dfb8f17e5ca3e5310f55341daf6714 (Caused by NameResolutionError("<urllib3.connection.HTTPSConnection object at 0x000001C430AFEB00>: Failed to resolve 'fapi.binance.com' ([Errno 11001] getaddrinfo failed)"))

During handling of the above exception, another exception occurred:

Traceback (most recent call last):
  File "D:\admin\MES PROJETS\Bot de trading\core\trade_executor.py", line 334, in cancel_all_open_orders_if_no_position
    positions = client.futures_position_information(symbol=symbol)
  File "C:\Users\user\AppData\Local\Programs\Python\Python310\lib\site-packages\binance\client.py", line 7835, in futures_position_information
    return self._request_futures_api("get", "positionRisk", True, 3, data=params)
  File "C:\Users\user\AppData\Local\Programs\Python\Python310\lib\site-packages\binance\client.py", line 126, in _request_futures_api
    return self._request(method, uri, signed, force_params, **kwargs)
  File "C:\Users\user\AppData\Local\Programs\Python\Python310\lib\site-packages\binance\client.py", line 88, in _request
    self.response = getattr(self.session, method)(uri, headers=headers, data=data, **kwargs)
  File "C:\Users\user\AppData\Local\Programs\Python\Python310\lib\site-packages\requests\sessions.py", line 602, in get
    return self.request("GET", url, **kwargs)
  File "C:\Users\user\AppData\Local\Programs\Python\Python310\lib\site-packages\requests\sessions.py", line 589, in request
    resp = self.send(prep, **send_kwargs)
  File "C:\Users\user\AppData\Local\Programs\Python\Python310\lib\site-packages\requests\sessions.py", line 703, in send
    r = adapter.send(request, **kwargs)
  File "C:\Users\user\AppData\Local\Programs\Python\Python310\lib\site-packages\requests\adapters.py", line 700, in send
    raise ConnectionError(e, request=request)
requests.exceptions.ConnectionError: HTTPSConnectionPool(host='fapi.binance.com', port=443): Max retries exceeded with url: /fapi/v3/positionRisk?recvWindow=10000&symbol=ALGOUSDT&timestamp=1752354305592&signature=78b3c424170bc21c7ab84cbe6a3db9d586dfb8f17e5ca3e5310f55341daf6714 (Caused by NameResolutionError("<urllib3.connection.HTTPSConnection object at 0x000001C430AFEB00>: Failed to resolve 'fapi.binance.com' ([Errno 11001] getaddrinfo failed)"))

Sat Jul 12 23:48:45 2025 - Erreur : Traceback (most recent call last):
  File "D:\admin\MES PROJETS\Bot de trading\core\trade_executor.py", line 154, in open_trade
    order = retry_order_creation(lambda: client.futures_create_order(
  File "D:\admin\MES PROJETS\Bot de trading\core\trade_executor.py", line 79, in retry_order_creation
    raise last_exception
  File "D:\admin\MES PROJETS\Bot de trading\core\trade_executor.py", line 74, in retry_order_creation
    return order_fn()
  File "D:\admin\MES PROJETS\Bot de trading\core\trade_executor.py", line 154, in <lambda>
    order = retry_order_creation(lambda: client.futures_create_order(
  File "C:\Users\user\AppData\Local\Programs\Python\Python310\lib\site-packages\binance\client.py", line 7659, in futures_create_order
    return self._request_futures_api("post", "order", True, data=params)
  File "C:\Users\user\AppData\Local\Programs\Python\Python310\lib\site-packages\binance\client.py", line 126, in _request_futures_api
    return self._request(method, uri, signed, force_params, **kwargs)
  File "C:\Users\user\AppData\Local\Programs\Python\Python310\lib\site-packages\binance\client.py", line 89, in _request
    return self._handle_response(self.response)
  File "C:\Users\user\AppData\Local\Programs\Python\Python310\lib\site-packages\binance\client.py", line 98, in _handle_response
    raise BinanceAPIException(response, response.status_code, response.text)
binance.exceptions.BinanceAPIException: APIError(code=-2019): Margin is insufficient.

Sun Jul 13 00:07:21 2025 - Erreur : Traceback (most recent call last):
  File "D:\admin\MES PROJETS\Bot de trading\core\trade_executor.py", line 152, in open_trade
    order = retry_order_creation(lambda: client.futures_create_order(
  File "D:\admin\MES PROJETS\Bot de trading\core\trade_executor.py", line 79, in retry_order_creation
    raise last_exception
  File "D:\admin\MES PROJETS\Bot de trading\core\trade_executor.py", line 74, in retry_order_creation
    return order_fn()
  File "D:\admin\MES PROJETS\Bot de trading\core\trade_executor.py", line 152, in <lambda>
    order = retry_order_creation(lambda: client.futures_create_order(
  File "C:\Users\user\AppData\Local\Programs\Python\Python310\lib\site-packages\binance\client.py", line 7659, in futures_create_order
    return self._request_futures_api("post", "order", True, data=params)
  File "C:\Users\user\AppData\Local\Programs\Python\Python310\lib\site-packages\binance\client.py", line 126, in _request_futures_api
    return self._request(method, uri, signed, force_params, **kwargs)
  File "C:\Users\user\AppData\Local\Programs\Python\Python310\lib\site-packages\binance\client.py", line 89, in _request
    return self._handle_response(self.response)
  File "C:\Users\user\AppData\Local\Programs\Python\Python310\lib\site-packages\binance\client.py", line 98, in _handle_response
    raise BinanceAPIException(response, response.status_code, response.text)
binance.exceptions.BinanceAPIException: APIError(code=-2019): Margin is insufficient.

Sun Jul 13 00:26:38 2025 - Erreur : Traceback (most recent call last):
  File "D:\admin\MES PROJETS\Bot de trading\core\trade_executor.py", line 154, in open_trade
    order = retry_order_creation(lambda: client.futures_create_order(
  File "D:\admin\MES PROJETS\Bot de trading\core\trade_executor.py", line 79, in retry_order_creation
    raise last_exception
  File "D:\admin\MES PROJETS\Bot de trading\core\trade_executor.py", line 74, in retry_order_creation
    return order_fn()
  File "D:\admin\MES PROJETS\Bot de trading\core\trade_executor.py", line 154, in <lambda>
    order = retry_order_creation(lambda: client.futures_create_order(
  File "C:\Users\user\AppData\Local\Programs\Python\Python310\lib\site-packages\binance\client.py", line 7659, in futures_create_order
    return self._request_futures_api("post", "order", True, data=params)
  File "C:\Users\user\AppData\Local\Programs\Python\Python310\lib\site-packages\binance\client.py", line 126, in _request_futures_api
    return self._request(method, uri, signed, force_params, **kwargs)
  File "C:\Users\user\AppData\Local\Programs\Python\Python310\lib\site-packages\binance\client.py", line 89, in _request
    return self._handle_response(self.response)
  File "C:\Users\user\AppData\Local\Programs\Python\Python310\lib\site-packages\binance\client.py", line 98, in _handle_response
    raise BinanceAPIException(response, response.status_code, response.text)
binance.exceptions.BinanceAPIException: APIError(code=-2019): Margin is insufficient.

Sun Jul 13 02:01:33 2025 - Erreur : Traceback (most recent call last):
  File "D:\admin\MES PROJETS\Bot de trading\core\trade_executor.py", line 282, in close_position
    lev = int(pos['leverage'])
KeyError: 'leverage'

Sun Jul 13 02:16:37 2025 - Erreur : Traceback (most recent call last):
  File "D:\admin\MES PROJETS\Bot de trading\core\trade_executor.py", line 173, in open_trade
    order = retry_order_creation(lambda: client.futures_create_order(
  File "D:\admin\MES PROJETS\Bot de trading\core\trade_executor.py", line 79, in retry_order_creation
    raise last_exception
  File "D:\admin\MES PROJETS\Bot de trading\core\trade_executor.py", line 74, in retry_order_creation
    return order_fn()
  File "D:\admin\MES PROJETS\Bot de trading\core\trade_executor.py", line 173, in <lambda>
    order = retry_order_creation(lambda: client.futures_create_order(
  File "C:\Users\user\AppData\Local\Programs\Python\Python310\lib\site-packages\binance\client.py", line 7659, in futures_create_order
    return self._request_futures_api("post", "order", True, data=params)
  File "C:\Users\user\AppData\Local\Programs\Python\Python310\lib\site-packages\binance\client.py", line 126, in _request_futures_api
    return self._request(method, uri, signed, force_params, **kwargs)
  File "C:\Users\user\AppData\Local\Programs\Python\Python310\lib\site-packages\binance\client.py", line 89, in _request
    return self._handle_response(self.response)
  File "C:\Users\user\AppData\Local\Programs\Python\Python310\lib\site-packages\binance\client.py", line 98, in _handle_response
    raise BinanceAPIException(response, response.status_code, response.text)
binance.exceptions.BinanceAPIException: APIError(code=-4164): Order's notional must be no smaller than 5 (unless you choose reduce only).

Sun Jul 13 02:20:06 2025 - Erreur : Traceback (most recent call last):
  File "D:\admin\MES PROJETS\Bot de trading\core\trade_executor.py", line 283, in close_position
    for p in position_info:
NameError: name 'position_info' is not defined

